2025-06-19 23:23:38,960 [INFO] C:\Users\asd\Desktop\CollaborationTool-back\users\views\login_view.py changed, reloading.
2025-06-19 23:23:58,006 [WARNING] Unauthorized: /api/login/
2025-06-19 23:24:01,690 [WARNING] Unauthorized: /api/login/
2025-06-19 23:24:11,275 [WARNING] Unauthorized: /api/login/
2025-06-19 23:24:15,377 [WARNING] Unauthorized: /api/login/
2025-06-19 23:24:15,550 [WARNING] Unauthorized: /api/login/
2025-06-19 23:24:31,732 [WARNING] Unauthorized: /api/login/
2025-06-19 23:24:32,500 [WARNING] Unauthorized: /api/login/
2025-06-19 23:24:33,197 [WARNING] Unauthorized: /api/login/
2025-06-19 23:24:33,534 [WARNING] Unauthorized: /api/login/
2025-06-19 23:24:33,710 [WARNING] Unauthorized: /api/login/
2025-06-19 23:28:33,051 [INFO] C:\Users\asd\Desktop\CollaborationTool-back\users\views\login_view.py changed, reloading.
2025-06-19 23:29:40,072 [WARNING] Not Found: /api/tasks/todo/2
2025-06-19 23:29:40,074 [WARNING] Not Found: /api/tasks/todo/undefined
2025-06-19 23:29:40,077 [WARNING] Not Found: /api/getprojects
2025-06-19 23:29:40,623 [WARNING] Not Found: /api/tasks/todo/undefined
2025-06-19 23:29:50,080 [WARNING] Not Found: /api/getprojects
2025-06-19 23:29:50,093 [WARNING] Not Found: /api/tasks/todo/3
2025-06-19 23:29:50,507 [WARNING] Not Found: /api/tasks/todo/4
2025-06-19 23:29:50,511 [WARNING] Not Found: /api/getprojects
2025-06-19 23:29:52,656 [WARNING] Not Found: /api/task/card-1
2025-06-19 23:29:53,218 [WARNING] Not Found: /api/task/card-1
2025-06-19 23:31:11,514 [INFO] C:\Users\asd\Desktop\CollaborationTool-back\users\views\login_view.py changed, reloading.
2025-06-19 23:31:38,359 [WARNING] Unauthorized: /api/login/
2025-06-19 23:32:11,920 [WARNING] Unauthorized: /api/login/
2025-06-19 23:32:26,711 [WARNING] Not Found: /api/task/card-1
2025-06-19 23:32:31,319 [WARNING] Unauthorized: /api/login/
2025-06-19 23:33:28,621 [WARNING] Unauthorized: /api/login/
2025-06-19 23:34:58,541 [WARNING] Not Found: /api/task/card-1
2025-06-19 23:34:59,153 [WARNING] Not Found: /api/task/card-1
2025-06-19 23:34:59,354 [WARNING] Not Found: /api/task/card-1
2025-06-19 23:37:10,864 [INFO] C:\Users\asd\Desktop\CollaborationTool-back\users\urls.py changed, reloading.
2025-06-19 23:41:18,013 [WARNING] Not Found: /
2025-06-19 23:41:46,759 [INFO] C:\Users\asd\Desktop\CollaborationTool-back\users\views\login_view.py changed, reloading.
2025-06-19 23:41:54,152 [WARNING] Unauthorized: /api/login/
2025-06-19 23:42:04,875 [WARNING] Unauthorized: /api/login/
2025-06-19 23:43:23,276 [WARNING] Not Found: /api/tasks/todo/4
2025-06-19 23:43:23,823 [WARNING] Not Found: /api/tasks/todo/4
2025-06-19 23:43:28,389 [INFO] C:\Users\asd\Desktop\CollaborationTool-back\users\views\login_view.py changed, reloading.
2025-06-19 23:43:44,499 [INFO] C:\Users\asd\Desktop\CollaborationTool-back\users\views\login_view.py changed, reloading.
2025-06-19 23:43:56,436 [INFO] C:\Users\asd\Desktop\CollaborationTool-back\users\views\login_view.py changed, reloading.
2025-06-19 23:46:49,119 [INFO] C:\Users\asd\Desktop\CollaborationTool-back\users\views\login_view.py changed, reloading.
2025-06-19 23:47:09,381 [INFO] C:\Users\asd\Desktop\CollaborationTool-back\users\views\login_view.py changed, reloading.
2025-06-19 23:47:17,831 [WARNING] LoginView 진입 확인됨
2025-06-19 23:47:17,832 [DEBUG] 입력 이메일: rdh4879@naver.com
2025-06-19 23:47:17,832 [DEBUG] 입력 비밀번호: 1234
2025-06-19 23:47:17,837 [DEBUG] DB 조회된 유저: rdh4879@naver.com
2025-06-19 23:47:18,478 [WARNING] 비밀번호 불일치
2025-06-19 23:47:18,478 [DEBUG] 입력된 비밀번호: 1234
2025-06-19 23:47:18,478 [DEBUG] DB 해시: $2b$12$AxBIJDNlFWJoMX6rWT8oROkn00tmMRWi.ChY.ZDysOhnYN.amvcqC
2025-06-19 23:47:19,112 [DEBUG] check_password 결과: False
2025-06-19 23:47:19,745 [WARNING] Unauthorized: /api/login/
2025-06-19 23:47:20,980 [WARNING] LoginView 진입 확인됨
2025-06-19 23:47:20,980 [DEBUG] 입력 이메일: rdh4879@naver.com
2025-06-19 23:47:20,980 [DEBUG] 입력 비밀번호: 1234
2025-06-19 23:47:20,984 [DEBUG] DB 조회된 유저: rdh4879@naver.com
2025-06-19 23:47:21,613 [WARNING] 비밀번호 불일치
2025-06-19 23:47:21,613 [DEBUG] 입력된 비밀번호: 1234
2025-06-19 23:47:21,613 [DEBUG] DB 해시: $2b$12$AxBIJDNlFWJoMX6rWT8oROkn00tmMRWi.ChY.ZDysOhnYN.amvcqC
2025-06-19 23:47:22,237 [DEBUG] check_password 결과: False
2025-06-19 23:47:22,861 [WARNING] Unauthorized: /api/login/
2025-06-19 23:47:38,376 [WARNING] LoginView 진입 확인됨
2025-06-19 23:47:38,376 [DEBUG] 입력 이메일: rdh4879@naver.com
2025-06-19 23:47:38,376 [DEBUG] 입력 비밀번호: 1234
2025-06-19 23:47:38,378 [DEBUG] DB 조회된 유저: rdh4879@naver.com
2025-06-19 23:47:39,003 [WARNING] 비밀번호 불일치
2025-06-19 23:47:39,003 [DEBUG] 입력된 비밀번호: 1234
2025-06-19 23:47:39,003 [DEBUG] DB 해시: $2b$12$AxBIJDNlFWJoMX6rWT8oROkn00tmMRWi.ChY.ZDysOhnYN.amvcqC
2025-06-19 23:47:39,624 [DEBUG] check_password 결과: False
2025-06-19 23:47:40,250 [WARNING] Unauthorized: /api/login/
2025-06-19 23:50:53,599 [WARNING] LoginView 진입 확인됨
2025-06-19 23:50:53,600 [DEBUG] 입력 이메일: rdh4879@naver.com
2025-06-19 23:50:53,600 [DEBUG] 입력 비밀번호: 1234
2025-06-19 23:50:53,603 [DEBUG] DB 조회된 유저: rdh4879@naver.com
2025-06-19 23:50:54,881 [INFO] 로그인 성공: rdh4879@naver.com
2025-06-19 23:50:54,990 [WARNING] Not Found: /api/getprojects
2025-06-19 23:50:55,525 [WARNING] Not Found: /api/getprojects
2025-06-19 23:51:17,204 [WARNING] Not Found: /api/getprojects
2025-06-19 23:51:17,277 [WARNING] Not Found: /api/getprojects
2025-06-19 23:51:30,032 [WARNING] LoginView 진입 확인됨
2025-06-19 23:51:30,032 [DEBUG] 입력 이메일: aa@test.com
2025-06-19 23:51:30,032 [DEBUG] 입력 비밀번호: ㅁㅁ
2025-06-19 23:51:30,034 [DEBUG] DB 조회된 유저: aa@test.com
2025-06-19 23:51:30,658 [WARNING] 비밀번호 불일치
2025-06-19 23:51:30,658 [DEBUG] 입력된 비밀번호: ㅁㅁ
2025-06-19 23:51:30,658 [DEBUG] DB 해시: $2b$12$rTLdGmToM1D44kT5.NHooubbz0AEsfrcw80KQQGR3Vd0hXqV3IB8i
2025-06-19 23:51:31,287 [DEBUG] check_password 결과: False
2025-06-19 23:51:31,911 [WARNING] Unauthorized: /api/login/
2025-06-19 23:51:42,676 [WARNING] LoginView 진입 확인됨
2025-06-19 23:51:42,676 [DEBUG] 입력 이메일: aa@test.com
2025-06-19 23:51:42,676 [DEBUG] 입력 비밀번호: ㅁㅁ
2025-06-19 23:51:42,678 [DEBUG] DB 조회된 유저: aa@test.com
2025-06-19 23:51:43,305 [WARNING] 비밀번호 불일치
2025-06-19 23:51:43,305 [DEBUG] 입력된 비밀번호: ㅁㅁ
2025-06-19 23:51:43,305 [DEBUG] DB 해시: $2b$12$rTLdGmToM1D44kT5.NHooubbz0AEsfrcw80KQQGR3Vd0hXqV3IB8i
2025-06-19 23:51:43,935 [DEBUG] check_password 결과: False
2025-06-19 23:51:44,568 [WARNING] Unauthorized: /api/login/
2025-06-19 23:53:59,762 [WARNING] LoginView 진입 확인됨
2025-06-19 23:53:59,763 [DEBUG] 입력 이메일: aa@test.com
2025-06-19 23:53:59,763 [DEBUG] 입력 비밀번호: 1234
2025-06-19 23:53:59,766 [DEBUG] DB 조회된 유저: aa@test.com
2025-06-19 23:53:59,969 [WARNING] LoginView 진입 확인됨
2025-06-19 23:53:59,969 [DEBUG] 입력 이메일: aa@test.com
2025-06-19 23:53:59,969 [DEBUG] 입력 비밀번호: 1234
2025-06-19 23:53:59,972 [DEBUG] DB 조회된 유저: aa@test.com
2025-06-19 23:54:01,098 [INFO] 로그인 성공: aa@test.com
2025-06-19 23:54:01,200 [WARNING] Not Found: /api/getprojects
2025-06-19 23:54:01,295 [INFO] 로그인 성공: aa@test.com
2025-06-19 23:54:01,662 [WARNING] Not Found: /api/getprojects
2025-06-19 23:54:06,690 [WARNING] Not Found: /api/getprojects
2025-06-19 23:54:06,831 [WARNING] Not Found: /api/getprojects
2025-06-19 23:54:45,235 [WARNING] Not Found: /api/tasks/todo/undefined
2025-06-19 23:54:45,238 [WARNING] Not Found: /api/tasks/todo/2
2025-06-19 23:54:45,241 [WARNING] Not Found: /api/getprojects
2025-06-19 23:54:45,830 [WARNING] Not Found: /api/tasks/todo/undefined
2025-06-19 23:54:47,424 [WARNING] Not Found: /api/task/card-2
2025-06-19 23:54:49,506 [WARNING] Not Found: /api/tasks/todo/undefined
2025-06-19 23:54:49,508 [WARNING] Not Found: /api/tasks/todo/2
2025-06-19 23:54:49,511 [WARNING] Not Found: /api/getprojects
2025-06-19 23:54:49,800 [WARNING] Not Found: /api/tasks/todo/undefined
2025-06-19 23:54:59,958 [WARNING] Not Found: /api/project
2025-06-19 23:54:59,965 [WARNING] Not Found: /api/project
2025-06-19 23:55:00,174 [WARNING] Not Found: /api/project
2025-06-19 23:55:00,211 [WARNING] Not Found: /api/project
2025-06-19 23:55:00,399 [WARNING] Not Found: /api/project
2025-06-19 23:55:00,993 [WARNING] Not Found: /api/project
2025-06-19 23:55:01,141 [WARNING] Not Found: /api/project
2025-06-19 23:55:01,278 [WARNING] Not Found: /api/project
2025-06-19 23:55:01,427 [WARNING] Not Found: /api/project
2025-06-19 23:55:01,562 [WARNING] Not Found: /api/project
2025-06-19 23:55:01,703 [WARNING] Not Found: /api/project
2025-06-19 23:55:01,865 [WARNING] Not Found: /api/project
2025-06-19 23:55:02,003 [WARNING] Not Found: /api/project
2025-06-19 23:55:02,186 [WARNING] Not Found: /api/project
2025-06-19 23:55:02,325 [WARNING] Not Found: /api/project
2025-06-20 01:39:03,749 [INFO] C:\Users\asd\Desktop\CollaborationTool-back\users\urls.py changed, reloading.
2025-06-20 01:39:12,564 [INFO] C:\Users\asd\Desktop\CollaborationTool-back\users\urls.py changed, reloading.
2025-06-20 09:59:11,392 [WARNING] Not Found: /
2025-06-20 09:59:11,395 [WARNING] Not Found: /
2025-06-20 09:59:11,398 [WARNING] Not Found: /
2025-06-20 13:44:33,520 [WARNING] LoginView 진입 확인됨
2025-06-20 13:44:33,520 [DEBUG] 입력 이메일: rdh4879@naver.com
2025-06-20 13:44:33,521 [DEBUG] 입력 비밀번호: 1234
2025-06-20 13:44:33,525 [DEBUG] DB 조회된 유저: rdh4879@naver.com
2025-06-20 13:44:33,988 [WARNING] LoginView 진입 확인됨
2025-06-20 13:44:33,988 [DEBUG] 입력 이메일: rdh4879@naver.com
2025-06-20 13:44:33,988 [DEBUG] 입력 비밀번호: 1234
2025-06-20 13:44:33,991 [DEBUG] DB 조회된 유저: rdh4879@naver.com
2025-06-20 13:44:34,851 [INFO] 로그인 성공: rdh4879@naver.com
2025-06-20 13:44:35,007 [WARNING] Not Found: /api/getprojects
2025-06-20 13:44:35,307 [INFO] 로그인 성공: rdh4879@naver.com
2025-06-20 13:44:35,548 [WARNING] Not Found: /api/getprojects
2025-06-20 13:51:26,640 [INFO] C:\Users\asd\Desktop\CollaborationTool-back\projects\views\create_project_view.py changed, reloading.
2025-06-20 13:51:47,206 [INFO] C:\Users\asd\Desktop\CollaborationTool-back\SWE\urls.py changed, reloading.
2025-06-20 13:52:03,367 [INFO] C:\Users\asd\Desktop\CollaborationTool-back\SWE\urls.py changed, reloading.
2025-06-20 13:54:26,581 [WARNING] Unauthorized: /api/project
2025-06-20 13:55:21,057 [WARNING] Unauthorized: /api/token/refresh/
2025-06-20 13:56:00,872 [ERROR] Internal Server Error: /api/login
Traceback (most recent call last):
  File "C:\Users\asd\Desktop\소공서버\venv\Lib\site-packages\django\core\handlers\exception.py", line 55, in inner
    response = get_response(request)
               ^^^^^^^^^^^^^^^^^^^^^
  File "C:\Users\asd\Desktop\소공서버\venv\Lib\site-packages\django\utils\deprecation.py", line 122, in __call__
    response = self.process_response(request, response)
               ^^^^^^^^^^^^^^^^^^^^^^^^^^^^^^^^^^^^^^^^
  File "C:\Users\asd\Desktop\소공서버\venv\Lib\site-packages\django\middleware\common.py", line 108, in process_response
    return self.response_redirect_class(self.get_full_path_with_slash(request))
                                        ^^^^^^^^^^^^^^^^^^^^^^^^^^^^^^^^^^^^^^
  File "C:\Users\asd\Desktop\소공서버\venv\Lib\site-packages\django\middleware\common.py", line 87, in get_full_path_with_slash
    raise RuntimeError(
RuntimeError: You called this URL via POST, but the URL doesn't end in a slash and you have APPEND_SLASH set. Django can't redirect to the slash URL while maintaining POST data. Change your form to point to 127.0.0.1:8000/api/login/ (note the trailing slash), or set APPEND_SLASH=False in your Django settings.
2025-06-20 13:56:16,738 [WARNING] Not Found: /api/logins
2025-06-20 13:56:23,351 [ERROR] Internal Server Error: /api/login
Traceback (most recent call last):
  File "C:\Users\asd\Desktop\소공서버\venv\Lib\site-packages\django\core\handlers\exception.py", line 55, in inner
    response = get_response(request)
               ^^^^^^^^^^^^^^^^^^^^^
  File "C:\Users\asd\Desktop\소공서버\venv\Lib\site-packages\django\utils\deprecation.py", line 122, in __call__
    response = self.process_response(request, response)
               ^^^^^^^^^^^^^^^^^^^^^^^^^^^^^^^^^^^^^^^^
  File "C:\Users\asd\Desktop\소공서버\venv\Lib\site-packages\django\middleware\common.py", line 108, in process_response
    return self.response_redirect_class(self.get_full_path_with_slash(request))
                                        ^^^^^^^^^^^^^^^^^^^^^^^^^^^^^^^^^^^^^^
  File "C:\Users\asd\Desktop\소공서버\venv\Lib\site-packages\django\middleware\common.py", line 87, in get_full_path_with_slash
    raise RuntimeError(
RuntimeError: You called this URL via POST, but the URL doesn't end in a slash and you have APPEND_SLASH set. Django can't redirect to the slash URL while maintaining POST data. Change your form to point to 127.0.0.1:8000/api/login/ (note the trailing slash), or set APPEND_SLASH=False in your Django settings.
2025-06-20 13:56:36,501 [ERROR] Internal Server Error: /api/login
Traceback (most recent call last):
  File "C:\Users\asd\Desktop\소공서버\venv\Lib\site-packages\django\core\handlers\exception.py", line 55, in inner
    response = get_response(request)
               ^^^^^^^^^^^^^^^^^^^^^
  File "C:\Users\asd\Desktop\소공서버\venv\Lib\site-packages\django\utils\deprecation.py", line 122, in __call__
    response = self.process_response(request, response)
               ^^^^^^^^^^^^^^^^^^^^^^^^^^^^^^^^^^^^^^^^
  File "C:\Users\asd\Desktop\소공서버\venv\Lib\site-packages\django\middleware\common.py", line 108, in process_response
    return self.response_redirect_class(self.get_full_path_with_slash(request))
                                        ^^^^^^^^^^^^^^^^^^^^^^^^^^^^^^^^^^^^^^
  File "C:\Users\asd\Desktop\소공서버\venv\Lib\site-packages\django\middleware\common.py", line 87, in get_full_path_with_slash
    raise RuntimeError(
RuntimeError: You called this URL via POST, but the URL doesn't end in a slash and you have APPEND_SLASH set. Django can't redirect to the slash URL while maintaining POST data. Change your form to point to 127.0.0.1:8000/api/login/ (note the trailing slash), or set APPEND_SLASH=False in your Django settings.
2025-06-20 13:56:52,003 [ERROR] Internal Server Error: /api/login
Traceback (most recent call last):
  File "C:\Users\asd\Desktop\소공서버\venv\Lib\site-packages\django\core\handlers\exception.py", line 55, in inner
    response = get_response(request)
               ^^^^^^^^^^^^^^^^^^^^^
  File "C:\Users\asd\Desktop\소공서버\venv\Lib\site-packages\django\utils\deprecation.py", line 122, in __call__
    response = self.process_response(request, response)
               ^^^^^^^^^^^^^^^^^^^^^^^^^^^^^^^^^^^^^^^^
  File "C:\Users\asd\Desktop\소공서버\venv\Lib\site-packages\django\middleware\common.py", line 108, in process_response
    return self.response_redirect_class(self.get_full_path_with_slash(request))
                                        ^^^^^^^^^^^^^^^^^^^^^^^^^^^^^^^^^^^^^^
  File "C:\Users\asd\Desktop\소공서버\venv\Lib\site-packages\django\middleware\common.py", line 87, in get_full_path_with_slash
    raise RuntimeError(
RuntimeError: You called this URL via POST, but the URL doesn't end in a slash and you have APPEND_SLASH set. Django can't redirect to the slash URL while maintaining POST data. Change your form to point to 127.0.0.1:8000/api/login/ (note the trailing slash), or set APPEND_SLASH=False in your Django settings.
2025-06-20 13:56:54,706 [ERROR] Internal Server Error: /api/login
Traceback (most recent call last):
  File "C:\Users\asd\Desktop\소공서버\venv\Lib\site-packages\django\core\handlers\exception.py", line 55, in inner
    response = get_response(request)
               ^^^^^^^^^^^^^^^^^^^^^
  File "C:\Users\asd\Desktop\소공서버\venv\Lib\site-packages\django\utils\deprecation.py", line 122, in __call__
    response = self.process_response(request, response)
               ^^^^^^^^^^^^^^^^^^^^^^^^^^^^^^^^^^^^^^^^
  File "C:\Users\asd\Desktop\소공서버\venv\Lib\site-packages\django\middleware\common.py", line 108, in process_response
    return self.response_redirect_class(self.get_full_path_with_slash(request))
                                        ^^^^^^^^^^^^^^^^^^^^^^^^^^^^^^^^^^^^^^
  File "C:\Users\asd\Desktop\소공서버\venv\Lib\site-packages\django\middleware\common.py", line 87, in get_full_path_with_slash
    raise RuntimeError(
RuntimeError: You called this URL via POST, but the URL doesn't end in a slash and you have APPEND_SLASH set. Django can't redirect to the slash URL while maintaining POST data. Change your form to point to 127.0.0.1:8000/api/login/ (note the trailing slash), or set APPEND_SLASH=False in your Django settings.
2025-06-20 13:57:15,667 [WARNING] Method Not Allowed: /api/login/
2025-06-20 13:57:15,807 [WARNING] Not Found: /favicon.ico
2025-06-20 13:58:36,737 [ERROR] Internal Server Error: /api/login
Traceback (most recent call last):
  File "C:\Users\asd\Desktop\소공서버\venv\Lib\site-packages\django\core\handlers\exception.py", line 55, in inner
    response = get_response(request)
               ^^^^^^^^^^^^^^^^^^^^^
  File "C:\Users\asd\Desktop\소공서버\venv\Lib\site-packages\django\utils\deprecation.py", line 122, in __call__
    response = self.process_response(request, response)
               ^^^^^^^^^^^^^^^^^^^^^^^^^^^^^^^^^^^^^^^^
  File "C:\Users\asd\Desktop\소공서버\venv\Lib\site-packages\django\middleware\common.py", line 108, in process_response
    return self.response_redirect_class(self.get_full_path_with_slash(request))
                                        ^^^^^^^^^^^^^^^^^^^^^^^^^^^^^^^^^^^^^^
  File "C:\Users\asd\Desktop\소공서버\venv\Lib\site-packages\django\middleware\common.py", line 87, in get_full_path_with_slash
    raise RuntimeError(
RuntimeError: You called this URL via POST, but the URL doesn't end in a slash and you have APPEND_SLASH set. Django can't redirect to the slash URL while maintaining POST data. Change your form to point to 127.0.0.1:8000/api/login/ (note the trailing slash), or set APPEND_SLASH=False in your Django settings.
2025-06-20 13:58:43,261 [ERROR] Internal Server Error: /api/login
Traceback (most recent call last):
  File "C:\Users\asd\Desktop\소공서버\venv\Lib\site-packages\django\core\handlers\exception.py", line 55, in inner
    response = get_response(request)
               ^^^^^^^^^^^^^^^^^^^^^
  File "C:\Users\asd\Desktop\소공서버\venv\Lib\site-packages\django\utils\deprecation.py", line 122, in __call__
    response = self.process_response(request, response)
               ^^^^^^^^^^^^^^^^^^^^^^^^^^^^^^^^^^^^^^^^
  File "C:\Users\asd\Desktop\소공서버\venv\Lib\site-packages\django\middleware\common.py", line 108, in process_response
    return self.response_redirect_class(self.get_full_path_with_slash(request))
                                        ^^^^^^^^^^^^^^^^^^^^^^^^^^^^^^^^^^^^^^
  File "C:\Users\asd\Desktop\소공서버\venv\Lib\site-packages\django\middleware\common.py", line 87, in get_full_path_with_slash
    raise RuntimeError(
RuntimeError: You called this URL via POST, but the URL doesn't end in a slash and you have APPEND_SLASH set. Django can't redirect to the slash URL while maintaining POST data. Change your form to point to 127.0.0.1:8000/api/login/ (note the trailing slash), or set APPEND_SLASH=False in your Django settings.
2025-06-20 13:59:05,419 [ERROR] Internal Server Error: /api/login
Traceback (most recent call last):
  File "C:\Users\asd\Desktop\소공서버\venv\Lib\site-packages\django\core\handlers\exception.py", line 55, in inner
    response = get_response(request)
               ^^^^^^^^^^^^^^^^^^^^^
  File "C:\Users\asd\Desktop\소공서버\venv\Lib\site-packages\django\utils\deprecation.py", line 122, in __call__
    response = self.process_response(request, response)
               ^^^^^^^^^^^^^^^^^^^^^^^^^^^^^^^^^^^^^^^^
  File "C:\Users\asd\Desktop\소공서버\venv\Lib\site-packages\django\middleware\common.py", line 108, in process_response
    return self.response_redirect_class(self.get_full_path_with_slash(request))
                                        ^^^^^^^^^^^^^^^^^^^^^^^^^^^^^^^^^^^^^^
  File "C:\Users\asd\Desktop\소공서버\venv\Lib\site-packages\django\middleware\common.py", line 87, in get_full_path_with_slash
    raise RuntimeError(
RuntimeError: You called this URL via POST, but the URL doesn't end in a slash and you have APPEND_SLASH set. Django can't redirect to the slash URL while maintaining POST data. Change your form to point to 127.0.0.1:8000/api/login/ (note the trailing slash), or set APPEND_SLASH=False in your Django settings.
2025-06-20 14:01:56,793 [INFO] C:\Users\asd\Desktop\CollaborationTool-back\users\views\login_view.py changed, reloading.
2025-06-20 14:02:29,819 [INFO] C:\Users\asd\Desktop\CollaborationTool-back\users\views\login_view.py changed, reloading.
2025-06-20 14:02:57,685 [ERROR] Internal Server Error: /api/login
Traceback (most recent call last):
  File "C:\Users\asd\Desktop\소공서버\venv\Lib\site-packages\django\core\handlers\exception.py", line 55, in inner
    response = get_response(request)
               ^^^^^^^^^^^^^^^^^^^^^
  File "C:\Users\asd\Desktop\소공서버\venv\Lib\site-packages\django\utils\deprecation.py", line 122, in __call__
    response = self.process_response(request, response)
               ^^^^^^^^^^^^^^^^^^^^^^^^^^^^^^^^^^^^^^^^
  File "C:\Users\asd\Desktop\소공서버\venv\Lib\site-packages\django\middleware\common.py", line 108, in process_response
    return self.response_redirect_class(self.get_full_path_with_slash(request))
                                        ^^^^^^^^^^^^^^^^^^^^^^^^^^^^^^^^^^^^^^
  File "C:\Users\asd\Desktop\소공서버\venv\Lib\site-packages\django\middleware\common.py", line 87, in get_full_path_with_slash
    raise RuntimeError(
RuntimeError: You called this URL via POST, but the URL doesn't end in a slash and you have APPEND_SLASH set. Django can't redirect to the slash URL while maintaining POST data. Change your form to point to 127.0.0.1:8000/api/login/ (note the trailing slash), or set APPEND_SLASH=False in your Django settings.
2025-06-20 14:03:09,271 [ERROR] Internal Server Error: /api/login
Traceback (most recent call last):
  File "C:\Users\asd\Desktop\소공서버\venv\Lib\site-packages\django\core\handlers\exception.py", line 55, in inner
    response = get_response(request)
               ^^^^^^^^^^^^^^^^^^^^^
  File "C:\Users\asd\Desktop\소공서버\venv\Lib\site-packages\django\utils\deprecation.py", line 122, in __call__
    response = self.process_response(request, response)
               ^^^^^^^^^^^^^^^^^^^^^^^^^^^^^^^^^^^^^^^^
  File "C:\Users\asd\Desktop\소공서버\venv\Lib\site-packages\django\middleware\common.py", line 108, in process_response
    return self.response_redirect_class(self.get_full_path_with_slash(request))
                                        ^^^^^^^^^^^^^^^^^^^^^^^^^^^^^^^^^^^^^^
  File "C:\Users\asd\Desktop\소공서버\venv\Lib\site-packages\django\middleware\common.py", line 87, in get_full_path_with_slash
    raise RuntimeError(
RuntimeError: You called this URL via POST, but the URL doesn't end in a slash and you have APPEND_SLASH set. Django can't redirect to the slash URL while maintaining POST data. Change your form to point to 127.0.0.1:8000/api/login/ (note the trailing slash), or set APPEND_SLASH=False in your Django settings.
2025-06-20 14:03:38,975 [WARNING] LoginView 진입 확인됨
2025-06-20 14:03:38,975 [DEBUG] 입력 이메일: rdh4879@naver.com
2025-06-20 14:03:38,975 [DEBUG] 입력 비밀번호: 1234
2025-06-20 14:03:38,978 [DEBUG] DB 조회된 유저: rdh4879@naver.com
2025-06-20 14:03:39,618 [INFO] 로그인 성공: rdh4879@naver.com
2025-06-20 14:05:06,305 [WARNING] Unauthorized: /api/project
2025-06-20 14:06:15,381 [WARNING] Unauthorized: /api/project
2025-06-20 14:06:25,190 [WARNING] Unauthorized: /api/project
2025-06-20 14:07:08,213 [WARNING] Not Found: /api/project/
2025-06-20 14:07:25,062 [WARNING] Unauthorized: /api/token/
2025-06-20 14:10:44,529 [WARNING] Unauthorized: /api/project
2025-06-20 14:11:15,754 [WARNING] Unauthorized: /api/project
2025-06-20 14:14:38,434 [INFO] C:\Users\asd\Desktop\CollaborationTool-back\projects\views\create_project_view.py changed, reloading.
2025-06-20 14:14:50,315 [INFO] C:\Users\asd\Desktop\CollaborationTool-back\projects\views\create_project_view.py changed, reloading.
2025-06-20 14:15:09,108 [WARNING] Unauthorized: /api/project
2025-06-20 14:15:10,432 [WARNING] Unauthorized: /api/project
2025-06-20 14:15:48,618 [INFO] C:\Users\asd\Desktop\CollaborationTool-back\SWE\urls.py changed, reloading.
2025-06-20 14:17:44,540 [INFO] C:\Users\asd\Desktop\CollaborationTool-back\projects\views\create_project_view.py changed, reloading.
2025-06-20 14:17:58,232 [WARNING] Unauthorized: /api/project/
2025-06-20 14:27:11,406 [WARNING] LoginView 진입 확인됨
2025-06-20 14:27:11,407 [DEBUG] 입력 이메일: rdh4879@naver.com
2025-06-20 14:27:11,408 [DEBUG] 입력 비밀번호: 1234
2025-06-20 14:27:11,413 [DEBUG] DB 조회된 유저: rdh4879@naver.com
2025-06-20 14:27:12,041 [INFO] 로그인 성공: rdh4879@naver.com
2025-06-20 14:27:12,128 [WARNING] Not Found: /api/getprojects
2025-06-20 14:27:12,663 [WARNING] Not Found: /api/getprojects
2025-06-20 14:27:21,092 [WARNING] Unauthorized: /api/project/
2025-06-20 14:27:33,318 [WARNING] Unauthorized: /api/project/
2025-06-20 14:27:37,536 [WARNING] Not Found: /api/getprojects
2025-06-20 14:27:37,672 [WARNING] Not Found: /api/getprojects
2025-06-20 14:28:01,722 [WARNING] Unauthorized: /api/project/
2025-06-20 14:28:20,726 [WARNING] Unauthorized: /api/project/
2025-06-20 14:28:34,392 [WARNING] Unauthorized: /api/project/
2025-06-20 14:33:25,069 [WARNING] Unauthorized: /api/project/
2025-06-20 14:44:14,542 [WARNING] LoginView 진입 확인됨
2025-06-20 14:44:14,542 [DEBUG] 입력 이메일: rdh4879@naver.com
2025-06-20 14:44:14,543 [DEBUG] 입력 비밀번호: 1234
2025-06-20 14:44:14,548 [DEBUG] DB 조회된 유저: rdh4879@naver.com
2025-06-20 14:44:15,189 [INFO] 로그인 성공: rdh4879@naver.com
2025-06-20 14:44:15,288 [WARNING] Not Found: /api/getprojects
2025-06-20 14:44:15,816 [WARNING] Not Found: /api/getprojects
2025-06-20 14:44:26,127 [WARNING] Unauthorized: /api/project/
2025-06-20 14:44:34,896 [WARNING] Unauthorized: /api/project/
2025-06-20 14:46:55,281 [WARNING] Method Not Allowed: /api/token/
2025-06-20 14:46:57,017 [WARNING] Not Found: /favicon.ico
2025-06-20 14:47:16,172 [WARNING] Not Found: /
2025-06-20 14:59:07,034 [WARNING] Not Found: /api/getprojects
2025-06-20 14:59:07,571 [WARNING] Not Found: /api/getprojects
2025-06-20 14:59:19,305 [ERROR] Internal Server Error: /api/project/
Traceback (most recent call last):
  File "C:\Users\asd\Desktop\소공서버\venv\Lib\site-packages\django\core\handlers\exception.py", line 55, in inner
    response = get_response(request)
               ^^^^^^^^^^^^^^^^^^^^^
  File "C:\Users\asd\Desktop\소공서버\venv\Lib\site-packages\django\core\handlers\base.py", line 197, in _get_response
    response = wrapped_callback(request, *callback_args, **callback_kwargs)
               ^^^^^^^^^^^^^^^^^^^^^^^^^^^^^^^^^^^^^^^^^^^^^^^^^^^^^^^^^^^^
  File "C:\Users\asd\Desktop\소공서버\venv\Lib\site-packages\django\views\decorators\csrf.py", line 65, in _view_wrapper
    return view_func(request, *args, **kwargs)
           ^^^^^^^^^^^^^^^^^^^^^^^^^^^^^^^^^^^
  File "C:\Users\asd\Desktop\소공서버\venv\Lib\site-packages\django\views\generic\base.py", line 104, in view
    return self.dispatch(request, *args, **kwargs)
           ^^^^^^^^^^^^^^^^^^^^^^^^^^^^^^^^^^^^^^^
  File "C:\Users\asd\Desktop\소공서버\venv\Lib\site-packages\rest_framework\views.py", line 515, in dispatch
    response = self.handle_exception(exc)
               ^^^^^^^^^^^^^^^^^^^^^^^^^^
  File "C:\Users\asd\Desktop\소공서버\venv\Lib\site-packages\rest_framework\views.py", line 475, in handle_exception
    self.raise_uncaught_exception(exc)
  File "C:\Users\asd\Desktop\소공서버\venv\Lib\site-packages\rest_framework\views.py", line 486, in raise_uncaught_exception
    raise exc
  File "C:\Users\asd\Desktop\소공서버\venv\Lib\site-packages\rest_framework\views.py", line 512, in dispatch
    response = handler(request, *args, **kwargs)
               ^^^^^^^^^^^^^^^^^^^^^^^^^^^^^^^^^
  File "C:\Users\asd\Desktop\CollaborationTool-back\projects\views\create_project_view.py", line 51, in post
    access = bool(int(data.get("access", 0)))
                  ^^^^^^^^^^^^^^^^^^^^^^^^^^
ValueError: invalid literal for int() with base 10: ''
2025-06-20 14:59:28,002 [ERROR] Internal Server Error: /api/project/
Traceback (most recent call last):
  File "C:\Users\asd\Desktop\소공서버\venv\Lib\site-packages\django\core\handlers\exception.py", line 55, in inner
    response = get_response(request)
               ^^^^^^^^^^^^^^^^^^^^^
  File "C:\Users\asd\Desktop\소공서버\venv\Lib\site-packages\django\core\handlers\base.py", line 197, in _get_response
    response = wrapped_callback(request, *callback_args, **callback_kwargs)
               ^^^^^^^^^^^^^^^^^^^^^^^^^^^^^^^^^^^^^^^^^^^^^^^^^^^^^^^^^^^^
  File "C:\Users\asd\Desktop\소공서버\venv\Lib\site-packages\django\views\decorators\csrf.py", line 65, in _view_wrapper
    return view_func(request, *args, **kwargs)
           ^^^^^^^^^^^^^^^^^^^^^^^^^^^^^^^^^^^
  File "C:\Users\asd\Desktop\소공서버\venv\Lib\site-packages\django\views\generic\base.py", line 104, in view
    return self.dispatch(request, *args, **kwargs)
           ^^^^^^^^^^^^^^^^^^^^^^^^^^^^^^^^^^^^^^^
  File "C:\Users\asd\Desktop\소공서버\venv\Lib\site-packages\rest_framework\views.py", line 515, in dispatch
    response = self.handle_exception(exc)
               ^^^^^^^^^^^^^^^^^^^^^^^^^^
  File "C:\Users\asd\Desktop\소공서버\venv\Lib\site-packages\rest_framework\views.py", line 475, in handle_exception
    self.raise_uncaught_exception(exc)
  File "C:\Users\asd\Desktop\소공서버\venv\Lib\site-packages\rest_framework\views.py", line 486, in raise_uncaught_exception
    raise exc
  File "C:\Users\asd\Desktop\소공서버\venv\Lib\site-packages\rest_framework\views.py", line 512, in dispatch
    response = handler(request, *args, **kwargs)
               ^^^^^^^^^^^^^^^^^^^^^^^^^^^^^^^^^
  File "C:\Users\asd\Desktop\CollaborationTool-back\projects\views\create_project_view.py", line 51, in post
    access = bool(int(data.get("access", 0)))
                  ^^^^^^^^^^^^^^^^^^^^^^^^^^
ValueError: invalid literal for int() with base 10: ''
2025-06-20 15:01:28,304 [INFO] C:\Users\asd\Desktop\CollaborationTool-back\projects\views\create_project_view.py changed, reloading.
2025-06-20 15:02:24,638 [WARNING] Bad Request: /api/project/
2025-06-20 15:02:28,121 [WARNING] Bad Request: /api/project/
2025-06-20 15:02:45,980 [WARNING] Bad Request: /api/project/
2025-06-20 15:14:45,051 [WARNING] Not Found: /api/getprojects
2025-06-20 15:14:45,592 [WARNING] Not Found: /api/getprojects
2025-06-20 15:15:18,590 [ERROR] Internal Server Error: /api/project/
Traceback (most recent call last):
  File "C:\Users\asd\Desktop\소공서버\venv\Lib\site-packages\django\db\backends\utils.py", line 105, in _execute
    return self.cursor.execute(sql, params)
           ^^^^^^^^^^^^^^^^^^^^^^^^^^^^^^^^
  File "C:\Users\asd\Desktop\소공서버\venv\Lib\site-packages\django\db\backends\mysql\base.py", line 76, in execute
    return self.cursor.execute(query, args)
           ^^^^^^^^^^^^^^^^^^^^^^^^^^^^^^^^
  File "C:\Users\asd\Desktop\소공서버\venv\Lib\site-packages\MySQLdb\cursors.py", line 179, in execute
    res = self._query(mogrified_query)
          ^^^^^^^^^^^^^^^^^^^^^^^^^^^^
  File "C:\Users\asd\Desktop\소공서버\venv\Lib\site-packages\MySQLdb\cursors.py", line 330, in _query
    db.query(q)
  File "C:\Users\asd\Desktop\소공서버\venv\Lib\site-packages\MySQLdb\connections.py", line 280, in query
    _mysql.connection.query(self, query)
MySQLdb.IntegrityError: (1062, "Duplicate entry '2-rdh4879@naver.com' for key 'project_members.PRIMARY'")

The above exception was the direct cause of the following exception:

Traceback (most recent call last):
  File "C:\Users\asd\Desktop\소공서버\venv\Lib\site-packages\django\core\handlers\exception.py", line 55, in inner
    response = get_response(request)
               ^^^^^^^^^^^^^^^^^^^^^
  File "C:\Users\asd\Desktop\소공서버\venv\Lib\site-packages\django\core\handlers\base.py", line 197, in _get_response
    response = wrapped_callback(request, *callback_args, **callback_kwargs)
               ^^^^^^^^^^^^^^^^^^^^^^^^^^^^^^^^^^^^^^^^^^^^^^^^^^^^^^^^^^^^
  File "C:\Users\asd\Desktop\소공서버\venv\Lib\site-packages\django\views\decorators\csrf.py", line 65, in _view_wrapper
    return view_func(request, *args, **kwargs)
           ^^^^^^^^^^^^^^^^^^^^^^^^^^^^^^^^^^^
  File "C:\Users\asd\Desktop\소공서버\venv\Lib\site-packages\django\views\generic\base.py", line 104, in view
    return self.dispatch(request, *args, **kwargs)
           ^^^^^^^^^^^^^^^^^^^^^^^^^^^^^^^^^^^^^^^
  File "C:\Users\asd\Desktop\소공서버\venv\Lib\site-packages\rest_framework\views.py", line 515, in dispatch
    response = self.handle_exception(exc)
               ^^^^^^^^^^^^^^^^^^^^^^^^^^
  File "C:\Users\asd\Desktop\소공서버\venv\Lib\site-packages\rest_framework\views.py", line 475, in handle_exception
    self.raise_uncaught_exception(exc)
  File "C:\Users\asd\Desktop\소공서버\venv\Lib\site-packages\rest_framework\views.py", line 486, in raise_uncaught_exception
    raise exc
  File "C:\Users\asd\Desktop\소공서버\venv\Lib\site-packages\rest_framework\views.py", line 512, in dispatch
    response = handler(request, *args, **kwargs)
               ^^^^^^^^^^^^^^^^^^^^^^^^^^^^^^^^^
  File "C:\Users\asd\Desktop\CollaborationTool-back\projects\views\create_project_view.py", line 86, in post
    ProjectMember.objects.create(
  File "C:\Users\asd\Desktop\소공서버\venv\Lib\site-packages\django\db\models\manager.py", line 87, in manager_method
    return getattr(self.get_queryset(), name)(*args, **kwargs)
           ^^^^^^^^^^^^^^^^^^^^^^^^^^^^^^^^^^^^^^^^^^^^^^^^^^^
  File "C:\Users\asd\Desktop\소공서버\venv\Lib\site-packages\django\db\models\query.py", line 663, in create
    obj.save(force_insert=True, using=self.db)
  File "C:\Users\asd\Desktop\소공서버\venv\Lib\site-packages\django\db\models\base.py", line 902, in save
    self.save_base(
  File "C:\Users\asd\Desktop\소공서버\venv\Lib\site-packages\django\db\models\base.py", line 1008, in save_base
    updated = self._save_table(
              ^^^^^^^^^^^^^^^^^
  File "C:\Users\asd\Desktop\소공서버\venv\Lib\site-packages\django\db\models\base.py", line 1169, in _save_table
    results = self._do_insert(
              ^^^^^^^^^^^^^^^^
  File "C:\Users\asd\Desktop\소공서버\venv\Lib\site-packages\django\db\models\base.py", line 1210, in _do_insert
    return manager._insert(
           ^^^^^^^^^^^^^^^^
  File "C:\Users\asd\Desktop\소공서버\venv\Lib\site-packages\django\db\models\manager.py", line 87, in manager_method
    return getattr(self.get_queryset(), name)(*args, **kwargs)
           ^^^^^^^^^^^^^^^^^^^^^^^^^^^^^^^^^^^^^^^^^^^^^^^^^^^
  File "C:\Users\asd\Desktop\소공서버\venv\Lib\site-packages\django\db\models\query.py", line 1864, in _insert
    return query.get_compiler(using=using).execute_sql(returning_fields)
           ^^^^^^^^^^^^^^^^^^^^^^^^^^^^^^^^^^^^^^^^^^^^^^^^^^^^^^^^^^^^^
  File "C:\Users\asd\Desktop\소공서버\venv\Lib\site-packages\django\db\models\sql\compiler.py", line 1882, in execute_sql
    cursor.execute(sql, params)
  File "C:\Users\asd\Desktop\소공서버\venv\Lib\site-packages\django\db\backends\utils.py", line 122, in execute
    return super().execute(sql, params)
           ^^^^^^^^^^^^^^^^^^^^^^^^^^^^
  File "C:\Users\asd\Desktop\소공서버\venv\Lib\site-packages\django\db\backends\utils.py", line 79, in execute
    return self._execute_with_wrappers(
           ^^^^^^^^^^^^^^^^^^^^^^^^^^^^
  File "C:\Users\asd\Desktop\소공서버\venv\Lib\site-packages\django\db\backends\utils.py", line 92, in _execute_with_wrappers
    return executor(sql, params, many, context)
           ^^^^^^^^^^^^^^^^^^^^^^^^^^^^^^^^^^^^
  File "C:\Users\asd\Desktop\소공서버\venv\Lib\site-packages\django\db\backends\utils.py", line 100, in _execute
    with self.db.wrap_database_errors:
  File "C:\Users\asd\Desktop\소공서버\venv\Lib\site-packages\django\db\utils.py", line 91, in __exit__
    raise dj_exc_value.with_traceback(traceback) from exc_value
  File "C:\Users\asd\Desktop\소공서버\venv\Lib\site-packages\django\db\backends\utils.py", line 105, in _execute
    return self.cursor.execute(sql, params)
           ^^^^^^^^^^^^^^^^^^^^^^^^^^^^^^^^
  File "C:\Users\asd\Desktop\소공서버\venv\Lib\site-packages\django\db\backends\mysql\base.py", line 76, in execute
    return self.cursor.execute(query, args)
           ^^^^^^^^^^^^^^^^^^^^^^^^^^^^^^^^
  File "C:\Users\asd\Desktop\소공서버\venv\Lib\site-packages\MySQLdb\cursors.py", line 179, in execute
    res = self._query(mogrified_query)
          ^^^^^^^^^^^^^^^^^^^^^^^^^^^^
  File "C:\Users\asd\Desktop\소공서버\venv\Lib\site-packages\MySQLdb\cursors.py", line 330, in _query
    db.query(q)
  File "C:\Users\asd\Desktop\소공서버\venv\Lib\site-packages\MySQLdb\connections.py", line 280, in query
    _mysql.connection.query(self, query)
django.db.utils.IntegrityError: (1062, "Duplicate entry '2-rdh4879@naver.com' for key 'project_members.PRIMARY'")
2025-06-20 15:16:30,969 [ERROR] Internal Server Error: /api/project/
Traceback (most recent call last):
  File "C:\Users\asd\Desktop\소공서버\venv\Lib\site-packages\django\db\backends\utils.py", line 105, in _execute
    return self.cursor.execute(sql, params)
           ^^^^^^^^^^^^^^^^^^^^^^^^^^^^^^^^
  File "C:\Users\asd\Desktop\소공서버\venv\Lib\site-packages\django\db\backends\mysql\base.py", line 76, in execute
    return self.cursor.execute(query, args)
           ^^^^^^^^^^^^^^^^^^^^^^^^^^^^^^^^
  File "C:\Users\asd\Desktop\소공서버\venv\Lib\site-packages\MySQLdb\cursors.py", line 179, in execute
    res = self._query(mogrified_query)
          ^^^^^^^^^^^^^^^^^^^^^^^^^^^^
  File "C:\Users\asd\Desktop\소공서버\venv\Lib\site-packages\MySQLdb\cursors.py", line 330, in _query
    db.query(q)
  File "C:\Users\asd\Desktop\소공서버\venv\Lib\site-packages\MySQLdb\connections.py", line 280, in query
    _mysql.connection.query(self, query)
MySQLdb.IntegrityError: (1062, "Duplicate entry '3-rdh4879@naver.com' for key 'project_members.PRIMARY'")

The above exception was the direct cause of the following exception:

Traceback (most recent call last):
  File "C:\Users\asd\Desktop\소공서버\venv\Lib\site-packages\django\core\handlers\exception.py", line 55, in inner
    response = get_response(request)
               ^^^^^^^^^^^^^^^^^^^^^
  File "C:\Users\asd\Desktop\소공서버\venv\Lib\site-packages\django\core\handlers\base.py", line 197, in _get_response
    response = wrapped_callback(request, *callback_args, **callback_kwargs)
               ^^^^^^^^^^^^^^^^^^^^^^^^^^^^^^^^^^^^^^^^^^^^^^^^^^^^^^^^^^^^
  File "C:\Users\asd\Desktop\소공서버\venv\Lib\site-packages\django\views\decorators\csrf.py", line 65, in _view_wrapper
    return view_func(request, *args, **kwargs)
           ^^^^^^^^^^^^^^^^^^^^^^^^^^^^^^^^^^^
  File "C:\Users\asd\Desktop\소공서버\venv\Lib\site-packages\django\views\generic\base.py", line 104, in view
    return self.dispatch(request, *args, **kwargs)
           ^^^^^^^^^^^^^^^^^^^^^^^^^^^^^^^^^^^^^^^
  File "C:\Users\asd\Desktop\소공서버\venv\Lib\site-packages\rest_framework\views.py", line 515, in dispatch
    response = self.handle_exception(exc)
               ^^^^^^^^^^^^^^^^^^^^^^^^^^
  File "C:\Users\asd\Desktop\소공서버\venv\Lib\site-packages\rest_framework\views.py", line 475, in handle_exception
    self.raise_uncaught_exception(exc)
  File "C:\Users\asd\Desktop\소공서버\venv\Lib\site-packages\rest_framework\views.py", line 486, in raise_uncaught_exception
    raise exc
  File "C:\Users\asd\Desktop\소공서버\venv\Lib\site-packages\rest_framework\views.py", line 512, in dispatch
    response = handler(request, *args, **kwargs)
               ^^^^^^^^^^^^^^^^^^^^^^^^^^^^^^^^^
  File "C:\Users\asd\Desktop\CollaborationTool-back\projects\views\create_project_view.py", line 86, in post
    ProjectMember.objects.create(
  File "C:\Users\asd\Desktop\소공서버\venv\Lib\site-packages\django\db\models\manager.py", line 87, in manager_method
    return getattr(self.get_queryset(), name)(*args, **kwargs)
           ^^^^^^^^^^^^^^^^^^^^^^^^^^^^^^^^^^^^^^^^^^^^^^^^^^^
  File "C:\Users\asd\Desktop\소공서버\venv\Lib\site-packages\django\db\models\query.py", line 663, in create
    obj.save(force_insert=True, using=self.db)
  File "C:\Users\asd\Desktop\소공서버\venv\Lib\site-packages\django\db\models\base.py", line 902, in save
    self.save_base(
  File "C:\Users\asd\Desktop\소공서버\venv\Lib\site-packages\django\db\models\base.py", line 1008, in save_base
    updated = self._save_table(
              ^^^^^^^^^^^^^^^^^
  File "C:\Users\asd\Desktop\소공서버\venv\Lib\site-packages\django\db\models\base.py", line 1169, in _save_table
    results = self._do_insert(
              ^^^^^^^^^^^^^^^^
  File "C:\Users\asd\Desktop\소공서버\venv\Lib\site-packages\django\db\models\base.py", line 1210, in _do_insert
    return manager._insert(
           ^^^^^^^^^^^^^^^^
  File "C:\Users\asd\Desktop\소공서버\venv\Lib\site-packages\django\db\models\manager.py", line 87, in manager_method
    return getattr(self.get_queryset(), name)(*args, **kwargs)
           ^^^^^^^^^^^^^^^^^^^^^^^^^^^^^^^^^^^^^^^^^^^^^^^^^^^
  File "C:\Users\asd\Desktop\소공서버\venv\Lib\site-packages\django\db\models\query.py", line 1864, in _insert
    return query.get_compiler(using=using).execute_sql(returning_fields)
           ^^^^^^^^^^^^^^^^^^^^^^^^^^^^^^^^^^^^^^^^^^^^^^^^^^^^^^^^^^^^^
  File "C:\Users\asd\Desktop\소공서버\venv\Lib\site-packages\django\db\models\sql\compiler.py", line 1882, in execute_sql
    cursor.execute(sql, params)
  File "C:\Users\asd\Desktop\소공서버\venv\Lib\site-packages\django\db\backends\utils.py", line 122, in execute
    return super().execute(sql, params)
           ^^^^^^^^^^^^^^^^^^^^^^^^^^^^
  File "C:\Users\asd\Desktop\소공서버\venv\Lib\site-packages\django\db\backends\utils.py", line 79, in execute
    return self._execute_with_wrappers(
           ^^^^^^^^^^^^^^^^^^^^^^^^^^^^
  File "C:\Users\asd\Desktop\소공서버\venv\Lib\site-packages\django\db\backends\utils.py", line 92, in _execute_with_wrappers
    return executor(sql, params, many, context)
           ^^^^^^^^^^^^^^^^^^^^^^^^^^^^^^^^^^^^
  File "C:\Users\asd\Desktop\소공서버\venv\Lib\site-packages\django\db\backends\utils.py", line 100, in _execute
    with self.db.wrap_database_errors:
  File "C:\Users\asd\Desktop\소공서버\venv\Lib\site-packages\django\db\utils.py", line 91, in __exit__
    raise dj_exc_value.with_traceback(traceback) from exc_value
  File "C:\Users\asd\Desktop\소공서버\venv\Lib\site-packages\django\db\backends\utils.py", line 105, in _execute
    return self.cursor.execute(sql, params)
           ^^^^^^^^^^^^^^^^^^^^^^^^^^^^^^^^
  File "C:\Users\asd\Desktop\소공서버\venv\Lib\site-packages\django\db\backends\mysql\base.py", line 76, in execute
    return self.cursor.execute(query, args)
           ^^^^^^^^^^^^^^^^^^^^^^^^^^^^^^^^
  File "C:\Users\asd\Desktop\소공서버\venv\Lib\site-packages\MySQLdb\cursors.py", line 179, in execute
    res = self._query(mogrified_query)
          ^^^^^^^^^^^^^^^^^^^^^^^^^^^^
  File "C:\Users\asd\Desktop\소공서버\venv\Lib\site-packages\MySQLdb\cursors.py", line 330, in _query
    db.query(q)
  File "C:\Users\asd\Desktop\소공서버\venv\Lib\site-packages\MySQLdb\connections.py", line 280, in query
    _mysql.connection.query(self, query)
django.db.utils.IntegrityError: (1062, "Duplicate entry '3-rdh4879@naver.com' for key 'project_members.PRIMARY'")
2025-06-20 15:19:47,640 [INFO] C:\Users\asd\Desktop\CollaborationTool-back\projects\views\create_project_view.py changed, reloading.
2025-06-20 15:20:51,160 [INFO] C:\Users\asd\Desktop\CollaborationTool-back\projects\views\create_project_view.py changed, reloading.
2025-06-20 15:21:04,139 [INFO] C:\Users\asd\Desktop\CollaborationTool-back\projects\views\create_project_view.py changed, reloading.
2025-06-20 15:21:08,696 [INFO] C:\Users\asd\Desktop\CollaborationTool-back\projects\views\create_project_view.py changed, reloading.
2025-06-20 15:21:19,280 [WARNING] Not Found: /api/getprojects
2025-06-20 15:21:19,794 [WARNING] Not Found: /api/getprojects
2025-06-20 15:21:34,081 [WARNING] Not Found: /api/getprojects
2025-06-20 15:21:34,205 [WARNING] Not Found: /api/getprojects
2025-06-20 15:21:46,937 [WARNING] Unauthorized: /api/project/
2025-06-20 15:23:48,229 [WARNING] Not Found: /api/getprojects
2025-06-20 15:23:48,753 [WARNING] Not Found: /api/getprojects
2025-06-20 15:24:03,324 [WARNING] Not Found: /api/getprojects
2025-06-20 15:24:31,964 [WARNING] Not Found: /api/getprojects
2025-06-20 22:31:16,061 [INFO] C:\Users\asd\Desktop\CollaborationTool-back\SWE\settings.py changed, reloading.
2025-06-20 22:31:28,922 [INFO] C:\Users\asd\Desktop\CollaborationTool-back\SWE\settings.py changed, reloading.
2025-06-20 22:32:03,883 [INFO] C:\Users\asd\Desktop\CollaborationTool-back\tasks\apps.py changed, reloading.
2025-06-20 22:37:02,060 [INFO] C:\Users\asd\Desktop\CollaborationTool-back\tasks\models\tasklog.py changed, reloading.
2025-06-20 22:40:53,782 [INFO] C:\Users\asd\Desktop\CollaborationTool-back\tasks\models\tasklog.py changed, reloading.
2025-06-20 22:41:06,767 [INFO] C:\Users\asd\Desktop\CollaborationTool-back\tasks\models\tasktag.py changed, reloading.
2025-06-20 22:45:05,562 [INFO] C:\Users\asd\Desktop\CollaborationTool-back\tasks\models\tasktag.py changed, reloading.
2025-06-20 22:45:08,020 [INFO] C:\Users\asd\Desktop\CollaborationTool-back\tasks\models\tasktag.py changed, reloading.
2025-06-20 22:45:17,824 [INFO] C:\Users\asd\Desktop\CollaborationTool-back\tasks\models\tasktag.py changed, reloading.
2025-06-20 22:45:30,790 [INFO] C:\Users\asd\Desktop\CollaborationTool-back\tasks\models\tasklog.py changed, reloading.
2025-06-20 22:45:38,533 [INFO] C:\Users\asd\Desktop\CollaborationTool-back\tasks\models\tasklog.py changed, reloading.
2025-06-20 22:45:51,576 [INFO] C:\Users\asd\Desktop\CollaborationTool-back\tasks\models\tasklog.py changed, reloading.
2025-06-20 22:49:32,850 [INFO] C:\Users\asd\Desktop\CollaborationTool-back\tasks\models\tasktag.py changed, reloading.
2025-06-20 22:50:33,310 [WARNING] Not Found: /api/getprojects
2025-06-20 22:50:33,828 [WARNING] Not Found: /api/getprojects
2025-06-20 22:50:45,339 [WARNING] Unauthorized: /api/notifications/
2025-06-20 22:50:47,082 [WARNING] Not Found: /api/tasks/todo/undefined
2025-06-20 22:50:47,087 [WARNING] Not Found: /api/tasks/todo/2
2025-06-20 22:50:47,090 [WARNING] Not Found: /api/getprojects
2025-06-20 22:50:47,636 [WARNING] Not Found: /api/tasks/todo/undefined
2025-06-20 22:50:53,233 [WARNING] Not Found: /api/getprojects
2025-06-20 22:50:53,367 [WARNING] Not Found: /api/getprojects
2025-06-21 02:32:35,021 [WARNING] Not Found: /
2025-06-21 12:08:38,205 [WARNING] Not Found: /
2025-06-21 14:47:59,983 [WARNING] Not Found: /api/getprojects
2025-06-21 14:48:00,484 [WARNING] Not Found: /api/getprojects
2025-06-21 14:50:36,501 [WARNING] Not Found: /api/getprojects
2025-06-21 14:50:36,988 [WARNING] Not Found: /api/getprojects
2025-06-21 14:50:42,030 [WARNING] Not Found: /api/getprojects
2025-06-21 14:50:44,470 [WARNING] Not Found: /api/getprojects
2025-06-21 14:50:45,020 [WARNING] Not Found: /api/getprojects
2025-06-21 14:50:45,224 [WARNING] Not Found: /api/getprojects
2025-06-21 14:50:45,828 [WARNING] Not Found: /api/getprojects
2025-06-21 14:50:51,547 [WARNING] Not Found: /api/getprojects
2025-06-21 14:51:08,134 [ERROR] Internal Server Error: /api/project/
Traceback (most recent call last):
  File "C:\Users\asd\Desktop\소공서버\venv\Lib\site-packages\django\db\backends\utils.py", line 105, in _execute
    return self.cursor.execute(sql, params)
           ^^^^^^^^^^^^^^^^^^^^^^^^^^^^^^^^
  File "C:\Users\asd\Desktop\소공서버\venv\Lib\site-packages\django\db\backends\mysql\base.py", line 76, in execute
    return self.cursor.execute(query, args)
           ^^^^^^^^^^^^^^^^^^^^^^^^^^^^^^^^
  File "C:\Users\asd\Desktop\소공서버\venv\Lib\site-packages\MySQLdb\cursors.py", line 179, in execute
    res = self._query(mogrified_query)
          ^^^^^^^^^^^^^^^^^^^^^^^^^^^^
  File "C:\Users\asd\Desktop\소공서버\venv\Lib\site-packages\MySQLdb\cursors.py", line 330, in _query
    db.query(q)
  File "C:\Users\asd\Desktop\소공서버\venv\Lib\site-packages\MySQLdb\connections.py", line 280, in query
    _mysql.connection.query(self, query)
MySQLdb.DataError: (1265, "Data truncated for column 'role' at row 1")

The above exception was the direct cause of the following exception:

Traceback (most recent call last):
  File "C:\Users\asd\Desktop\소공서버\venv\Lib\site-packages\django\core\handlers\exception.py", line 55, in inner
    response = get_response(request)
               ^^^^^^^^^^^^^^^^^^^^^
  File "C:\Users\asd\Desktop\소공서버\venv\Lib\site-packages\django\core\handlers\base.py", line 197, in _get_response
    response = wrapped_callback(request, *callback_args, **callback_kwargs)
               ^^^^^^^^^^^^^^^^^^^^^^^^^^^^^^^^^^^^^^^^^^^^^^^^^^^^^^^^^^^^
  File "C:\Users\asd\Desktop\소공서버\venv\Lib\site-packages\django\views\decorators\csrf.py", line 65, in _view_wrapper
    return view_func(request, *args, **kwargs)
           ^^^^^^^^^^^^^^^^^^^^^^^^^^^^^^^^^^^
  File "C:\Users\asd\Desktop\소공서버\venv\Lib\site-packages\django\views\generic\base.py", line 104, in view
    return self.dispatch(request, *args, **kwargs)
           ^^^^^^^^^^^^^^^^^^^^^^^^^^^^^^^^^^^^^^^
  File "C:\Users\asd\Desktop\소공서버\venv\Lib\site-packages\rest_framework\views.py", line 515, in dispatch
    response = self.handle_exception(exc)
               ^^^^^^^^^^^^^^^^^^^^^^^^^^
  File "C:\Users\asd\Desktop\소공서버\venv\Lib\site-packages\rest_framework\views.py", line 475, in handle_exception
    self.raise_uncaught_exception(exc)
  File "C:\Users\asd\Desktop\소공서버\venv\Lib\site-packages\rest_framework\views.py", line 486, in raise_uncaught_exception
    raise exc
  File "C:\Users\asd\Desktop\소공서버\venv\Lib\site-packages\rest_framework\views.py", line 512, in dispatch
    response = handler(request, *args, **kwargs)
               ^^^^^^^^^^^^^^^^^^^^^^^^^^^^^^^^^
  File "C:\Users\asd\Desktop\CollaborationTool-back\projects\views\create_project_view.py", line 88, in post
    ProjectMember.objects.create(
  File "C:\Users\asd\Desktop\소공서버\venv\Lib\site-packages\django\db\models\manager.py", line 87, in manager_method
    return getattr(self.get_queryset(), name)(*args, **kwargs)
           ^^^^^^^^^^^^^^^^^^^^^^^^^^^^^^^^^^^^^^^^^^^^^^^^^^^
  File "C:\Users\asd\Desktop\소공서버\venv\Lib\site-packages\django\db\models\query.py", line 663, in create
    obj.save(force_insert=True, using=self.db)
  File "C:\Users\asd\Desktop\소공서버\venv\Lib\site-packages\django\db\models\base.py", line 902, in save
    self.save_base(
  File "C:\Users\asd\Desktop\소공서버\venv\Lib\site-packages\django\db\models\base.py", line 1008, in save_base
    updated = self._save_table(
              ^^^^^^^^^^^^^^^^^
  File "C:\Users\asd\Desktop\소공서버\venv\Lib\site-packages\django\db\models\base.py", line 1169, in _save_table
    results = self._do_insert(
              ^^^^^^^^^^^^^^^^
  File "C:\Users\asd\Desktop\소공서버\venv\Lib\site-packages\django\db\models\base.py", line 1210, in _do_insert
    return manager._insert(
           ^^^^^^^^^^^^^^^^
  File "C:\Users\asd\Desktop\소공서버\venv\Lib\site-packages\django\db\models\manager.py", line 87, in manager_method
    return getattr(self.get_queryset(), name)(*args, **kwargs)
           ^^^^^^^^^^^^^^^^^^^^^^^^^^^^^^^^^^^^^^^^^^^^^^^^^^^
  File "C:\Users\asd\Desktop\소공서버\venv\Lib\site-packages\django\db\models\query.py", line 1864, in _insert
    return query.get_compiler(using=using).execute_sql(returning_fields)
           ^^^^^^^^^^^^^^^^^^^^^^^^^^^^^^^^^^^^^^^^^^^^^^^^^^^^^^^^^^^^^
  File "C:\Users\asd\Desktop\소공서버\venv\Lib\site-packages\django\db\models\sql\compiler.py", line 1882, in execute_sql
    cursor.execute(sql, params)
  File "C:\Users\asd\Desktop\소공서버\venv\Lib\site-packages\django\db\backends\utils.py", line 122, in execute
    return super().execute(sql, params)
           ^^^^^^^^^^^^^^^^^^^^^^^^^^^^
  File "C:\Users\asd\Desktop\소공서버\venv\Lib\site-packages\django\db\backends\utils.py", line 79, in execute
    return self._execute_with_wrappers(
           ^^^^^^^^^^^^^^^^^^^^^^^^^^^^
  File "C:\Users\asd\Desktop\소공서버\venv\Lib\site-packages\django\db\backends\utils.py", line 92, in _execute_with_wrappers
    return executor(sql, params, many, context)
           ^^^^^^^^^^^^^^^^^^^^^^^^^^^^^^^^^^^^
  File "C:\Users\asd\Desktop\소공서버\venv\Lib\site-packages\django\db\backends\utils.py", line 100, in _execute
    with self.db.wrap_database_errors:
  File "C:\Users\asd\Desktop\소공서버\venv\Lib\site-packages\django\db\utils.py", line 91, in __exit__
    raise dj_exc_value.with_traceback(traceback) from exc_value
  File "C:\Users\asd\Desktop\소공서버\venv\Lib\site-packages\django\db\backends\utils.py", line 105, in _execute
    return self.cursor.execute(sql, params)
           ^^^^^^^^^^^^^^^^^^^^^^^^^^^^^^^^
  File "C:\Users\asd\Desktop\소공서버\venv\Lib\site-packages\django\db\backends\mysql\base.py", line 76, in execute
    return self.cursor.execute(query, args)
           ^^^^^^^^^^^^^^^^^^^^^^^^^^^^^^^^
  File "C:\Users\asd\Desktop\소공서버\venv\Lib\site-packages\MySQLdb\cursors.py", line 179, in execute
    res = self._query(mogrified_query)
          ^^^^^^^^^^^^^^^^^^^^^^^^^^^^
  File "C:\Users\asd\Desktop\소공서버\venv\Lib\site-packages\MySQLdb\cursors.py", line 330, in _query
    db.query(q)
  File "C:\Users\asd\Desktop\소공서버\venv\Lib\site-packages\MySQLdb\connections.py", line 280, in query
    _mysql.connection.query(self, query)
django.db.utils.DataError: (1265, "Data truncated for column 'role' at row 1")
2025-06-21 14:54:15,447 [WARNING] Unauthorized: /api/project/
2025-06-21 14:54:20,634 [WARNING] Not Found: /api/getprojects
2025-06-21 14:54:21,113 [WARNING] Not Found: /api/getprojects
2025-06-21 14:54:33,244 [WARNING] Not Found: /api/getprojects
2025-06-21 14:54:33,379 [WARNING] Not Found: /api/getprojects
2025-06-21 14:54:57,929 [ERROR] Internal Server Error: /api/project/
Traceback (most recent call last):
  File "C:\Users\asd\Desktop\소공서버\venv\Lib\site-packages\django\db\backends\utils.py", line 105, in _execute
    return self.cursor.execute(sql, params)
           ^^^^^^^^^^^^^^^^^^^^^^^^^^^^^^^^
  File "C:\Users\asd\Desktop\소공서버\venv\Lib\site-packages\django\db\backends\mysql\base.py", line 76, in execute
    return self.cursor.execute(query, args)
           ^^^^^^^^^^^^^^^^^^^^^^^^^^^^^^^^
  File "C:\Users\asd\Desktop\소공서버\venv\Lib\site-packages\MySQLdb\cursors.py", line 179, in execute
    res = self._query(mogrified_query)
          ^^^^^^^^^^^^^^^^^^^^^^^^^^^^
  File "C:\Users\asd\Desktop\소공서버\venv\Lib\site-packages\MySQLdb\cursors.py", line 330, in _query
    db.query(q)
  File "C:\Users\asd\Desktop\소공서버\venv\Lib\site-packages\MySQLdb\connections.py", line 280, in query
    _mysql.connection.query(self, query)
MySQLdb.DataError: (1265, "Data truncated for column 'role' at row 1")

The above exception was the direct cause of the following exception:

Traceback (most recent call last):
  File "C:\Users\asd\Desktop\소공서버\venv\Lib\site-packages\django\core\handlers\exception.py", line 55, in inner
    response = get_response(request)
               ^^^^^^^^^^^^^^^^^^^^^
  File "C:\Users\asd\Desktop\소공서버\venv\Lib\site-packages\django\core\handlers\base.py", line 197, in _get_response
    response = wrapped_callback(request, *callback_args, **callback_kwargs)
               ^^^^^^^^^^^^^^^^^^^^^^^^^^^^^^^^^^^^^^^^^^^^^^^^^^^^^^^^^^^^
  File "C:\Users\asd\Desktop\소공서버\venv\Lib\site-packages\django\views\decorators\csrf.py", line 65, in _view_wrapper
    return view_func(request, *args, **kwargs)
           ^^^^^^^^^^^^^^^^^^^^^^^^^^^^^^^^^^^
  File "C:\Users\asd\Desktop\소공서버\venv\Lib\site-packages\django\views\generic\base.py", line 104, in view
    return self.dispatch(request, *args, **kwargs)
           ^^^^^^^^^^^^^^^^^^^^^^^^^^^^^^^^^^^^^^^
  File "C:\Users\asd\Desktop\소공서버\venv\Lib\site-packages\rest_framework\views.py", line 515, in dispatch
    response = self.handle_exception(exc)
               ^^^^^^^^^^^^^^^^^^^^^^^^^^
  File "C:\Users\asd\Desktop\소공서버\venv\Lib\site-packages\rest_framework\views.py", line 475, in handle_exception
    self.raise_uncaught_exception(exc)
  File "C:\Users\asd\Desktop\소공서버\venv\Lib\site-packages\rest_framework\views.py", line 486, in raise_uncaught_exception
    raise exc
  File "C:\Users\asd\Desktop\소공서버\venv\Lib\site-packages\rest_framework\views.py", line 512, in dispatch
    response = handler(request, *args, **kwargs)
               ^^^^^^^^^^^^^^^^^^^^^^^^^^^^^^^^^
  File "C:\Users\asd\Desktop\CollaborationTool-back\projects\views\create_project_view.py", line 88, in post
    ProjectMember.objects.create(
  File "C:\Users\asd\Desktop\소공서버\venv\Lib\site-packages\django\db\models\manager.py", line 87, in manager_method
    return getattr(self.get_queryset(), name)(*args, **kwargs)
           ^^^^^^^^^^^^^^^^^^^^^^^^^^^^^^^^^^^^^^^^^^^^^^^^^^^
  File "C:\Users\asd\Desktop\소공서버\venv\Lib\site-packages\django\db\models\query.py", line 663, in create
    obj.save(force_insert=True, using=self.db)
  File "C:\Users\asd\Desktop\소공서버\venv\Lib\site-packages\django\db\models\base.py", line 902, in save
    self.save_base(
  File "C:\Users\asd\Desktop\소공서버\venv\Lib\site-packages\django\db\models\base.py", line 1008, in save_base
    updated = self._save_table(
              ^^^^^^^^^^^^^^^^^
  File "C:\Users\asd\Desktop\소공서버\venv\Lib\site-packages\django\db\models\base.py", line 1169, in _save_table
    results = self._do_insert(
              ^^^^^^^^^^^^^^^^
  File "C:\Users\asd\Desktop\소공서버\venv\Lib\site-packages\django\db\models\base.py", line 1210, in _do_insert
    return manager._insert(
           ^^^^^^^^^^^^^^^^
  File "C:\Users\asd\Desktop\소공서버\venv\Lib\site-packages\django\db\models\manager.py", line 87, in manager_method
    return getattr(self.get_queryset(), name)(*args, **kwargs)
           ^^^^^^^^^^^^^^^^^^^^^^^^^^^^^^^^^^^^^^^^^^^^^^^^^^^
  File "C:\Users\asd\Desktop\소공서버\venv\Lib\site-packages\django\db\models\query.py", line 1864, in _insert
    return query.get_compiler(using=using).execute_sql(returning_fields)
           ^^^^^^^^^^^^^^^^^^^^^^^^^^^^^^^^^^^^^^^^^^^^^^^^^^^^^^^^^^^^^
  File "C:\Users\asd\Desktop\소공서버\venv\Lib\site-packages\django\db\models\sql\compiler.py", line 1882, in execute_sql
    cursor.execute(sql, params)
  File "C:\Users\asd\Desktop\소공서버\venv\Lib\site-packages\django\db\backends\utils.py", line 122, in execute
    return super().execute(sql, params)
           ^^^^^^^^^^^^^^^^^^^^^^^^^^^^
  File "C:\Users\asd\Desktop\소공서버\venv\Lib\site-packages\django\db\backends\utils.py", line 79, in execute
    return self._execute_with_wrappers(
           ^^^^^^^^^^^^^^^^^^^^^^^^^^^^
  File "C:\Users\asd\Desktop\소공서버\venv\Lib\site-packages\django\db\backends\utils.py", line 92, in _execute_with_wrappers
    return executor(sql, params, many, context)
           ^^^^^^^^^^^^^^^^^^^^^^^^^^^^^^^^^^^^
  File "C:\Users\asd\Desktop\소공서버\venv\Lib\site-packages\django\db\backends\utils.py", line 100, in _execute
    with self.db.wrap_database_errors:
  File "C:\Users\asd\Desktop\소공서버\venv\Lib\site-packages\django\db\utils.py", line 91, in __exit__
    raise dj_exc_value.with_traceback(traceback) from exc_value
  File "C:\Users\asd\Desktop\소공서버\venv\Lib\site-packages\django\db\backends\utils.py", line 105, in _execute
    return self.cursor.execute(sql, params)
           ^^^^^^^^^^^^^^^^^^^^^^^^^^^^^^^^
  File "C:\Users\asd\Desktop\소공서버\venv\Lib\site-packages\django\db\backends\mysql\base.py", line 76, in execute
    return self.cursor.execute(query, args)
           ^^^^^^^^^^^^^^^^^^^^^^^^^^^^^^^^
  File "C:\Users\asd\Desktop\소공서버\venv\Lib\site-packages\MySQLdb\cursors.py", line 179, in execute
    res = self._query(mogrified_query)
          ^^^^^^^^^^^^^^^^^^^^^^^^^^^^
  File "C:\Users\asd\Desktop\소공서버\venv\Lib\site-packages\MySQLdb\cursors.py", line 330, in _query
    db.query(q)
  File "C:\Users\asd\Desktop\소공서버\venv\Lib\site-packages\MySQLdb\connections.py", line 280, in query
    _mysql.connection.query(self, query)
django.db.utils.DataError: (1265, "Data truncated for column 'role' at row 1")
2025-06-21 14:55:11,944 [ERROR] Internal Server Error: /api/project/
Traceback (most recent call last):
  File "C:\Users\asd\Desktop\소공서버\venv\Lib\site-packages\django\db\backends\utils.py", line 105, in _execute
    return self.cursor.execute(sql, params)
           ^^^^^^^^^^^^^^^^^^^^^^^^^^^^^^^^
  File "C:\Users\asd\Desktop\소공서버\venv\Lib\site-packages\django\db\backends\mysql\base.py", line 76, in execute
    return self.cursor.execute(query, args)
           ^^^^^^^^^^^^^^^^^^^^^^^^^^^^^^^^
  File "C:\Users\asd\Desktop\소공서버\venv\Lib\site-packages\MySQLdb\cursors.py", line 179, in execute
    res = self._query(mogrified_query)
          ^^^^^^^^^^^^^^^^^^^^^^^^^^^^
  File "C:\Users\asd\Desktop\소공서버\venv\Lib\site-packages\MySQLdb\cursors.py", line 330, in _query
    db.query(q)
  File "C:\Users\asd\Desktop\소공서버\venv\Lib\site-packages\MySQLdb\connections.py", line 280, in query
    _mysql.connection.query(self, query)
MySQLdb.DataError: (1265, "Data truncated for column 'role' at row 1")

The above exception was the direct cause of the following exception:

Traceback (most recent call last):
  File "C:\Users\asd\Desktop\소공서버\venv\Lib\site-packages\django\core\handlers\exception.py", line 55, in inner
    response = get_response(request)
               ^^^^^^^^^^^^^^^^^^^^^
  File "C:\Users\asd\Desktop\소공서버\venv\Lib\site-packages\django\core\handlers\base.py", line 197, in _get_response
    response = wrapped_callback(request, *callback_args, **callback_kwargs)
               ^^^^^^^^^^^^^^^^^^^^^^^^^^^^^^^^^^^^^^^^^^^^^^^^^^^^^^^^^^^^
  File "C:\Users\asd\Desktop\소공서버\venv\Lib\site-packages\django\views\decorators\csrf.py", line 65, in _view_wrapper
    return view_func(request, *args, **kwargs)
           ^^^^^^^^^^^^^^^^^^^^^^^^^^^^^^^^^^^
  File "C:\Users\asd\Desktop\소공서버\venv\Lib\site-packages\django\views\generic\base.py", line 104, in view
    return self.dispatch(request, *args, **kwargs)
           ^^^^^^^^^^^^^^^^^^^^^^^^^^^^^^^^^^^^^^^
  File "C:\Users\asd\Desktop\소공서버\venv\Lib\site-packages\rest_framework\views.py", line 515, in dispatch
    response = self.handle_exception(exc)
               ^^^^^^^^^^^^^^^^^^^^^^^^^^
  File "C:\Users\asd\Desktop\소공서버\venv\Lib\site-packages\rest_framework\views.py", line 475, in handle_exception
    self.raise_uncaught_exception(exc)
  File "C:\Users\asd\Desktop\소공서버\venv\Lib\site-packages\rest_framework\views.py", line 486, in raise_uncaught_exception
    raise exc
  File "C:\Users\asd\Desktop\소공서버\venv\Lib\site-packages\rest_framework\views.py", line 512, in dispatch
    response = handler(request, *args, **kwargs)
               ^^^^^^^^^^^^^^^^^^^^^^^^^^^^^^^^^
  File "C:\Users\asd\Desktop\CollaborationTool-back\projects\views\create_project_view.py", line 88, in post
    ProjectMember.objects.create(
  File "C:\Users\asd\Desktop\소공서버\venv\Lib\site-packages\django\db\models\manager.py", line 87, in manager_method
    return getattr(self.get_queryset(), name)(*args, **kwargs)
           ^^^^^^^^^^^^^^^^^^^^^^^^^^^^^^^^^^^^^^^^^^^^^^^^^^^
  File "C:\Users\asd\Desktop\소공서버\venv\Lib\site-packages\django\db\models\query.py", line 663, in create
    obj.save(force_insert=True, using=self.db)
  File "C:\Users\asd\Desktop\소공서버\venv\Lib\site-packages\django\db\models\base.py", line 902, in save
    self.save_base(
  File "C:\Users\asd\Desktop\소공서버\venv\Lib\site-packages\django\db\models\base.py", line 1008, in save_base
    updated = self._save_table(
              ^^^^^^^^^^^^^^^^^
  File "C:\Users\asd\Desktop\소공서버\venv\Lib\site-packages\django\db\models\base.py", line 1169, in _save_table
    results = self._do_insert(
              ^^^^^^^^^^^^^^^^
  File "C:\Users\asd\Desktop\소공서버\venv\Lib\site-packages\django\db\models\base.py", line 1210, in _do_insert
    return manager._insert(
           ^^^^^^^^^^^^^^^^
  File "C:\Users\asd\Desktop\소공서버\venv\Lib\site-packages\django\db\models\manager.py", line 87, in manager_method
    return getattr(self.get_queryset(), name)(*args, **kwargs)
           ^^^^^^^^^^^^^^^^^^^^^^^^^^^^^^^^^^^^^^^^^^^^^^^^^^^
  File "C:\Users\asd\Desktop\소공서버\venv\Lib\site-packages\django\db\models\query.py", line 1864, in _insert
    return query.get_compiler(using=using).execute_sql(returning_fields)
           ^^^^^^^^^^^^^^^^^^^^^^^^^^^^^^^^^^^^^^^^^^^^^^^^^^^^^^^^^^^^^
  File "C:\Users\asd\Desktop\소공서버\venv\Lib\site-packages\django\db\models\sql\compiler.py", line 1882, in execute_sql
    cursor.execute(sql, params)
  File "C:\Users\asd\Desktop\소공서버\venv\Lib\site-packages\django\db\backends\utils.py", line 122, in execute
    return super().execute(sql, params)
           ^^^^^^^^^^^^^^^^^^^^^^^^^^^^
  File "C:\Users\asd\Desktop\소공서버\venv\Lib\site-packages\django\db\backends\utils.py", line 79, in execute
    return self._execute_with_wrappers(
           ^^^^^^^^^^^^^^^^^^^^^^^^^^^^
  File "C:\Users\asd\Desktop\소공서버\venv\Lib\site-packages\django\db\backends\utils.py", line 92, in _execute_with_wrappers
    return executor(sql, params, many, context)
           ^^^^^^^^^^^^^^^^^^^^^^^^^^^^^^^^^^^^
  File "C:\Users\asd\Desktop\소공서버\venv\Lib\site-packages\django\db\backends\utils.py", line 100, in _execute
    with self.db.wrap_database_errors:
  File "C:\Users\asd\Desktop\소공서버\venv\Lib\site-packages\django\db\utils.py", line 91, in __exit__
    raise dj_exc_value.with_traceback(traceback) from exc_value
  File "C:\Users\asd\Desktop\소공서버\venv\Lib\site-packages\django\db\backends\utils.py", line 105, in _execute
    return self.cursor.execute(sql, params)
           ^^^^^^^^^^^^^^^^^^^^^^^^^^^^^^^^
  File "C:\Users\asd\Desktop\소공서버\venv\Lib\site-packages\django\db\backends\mysql\base.py", line 76, in execute
    return self.cursor.execute(query, args)
           ^^^^^^^^^^^^^^^^^^^^^^^^^^^^^^^^
  File "C:\Users\asd\Desktop\소공서버\venv\Lib\site-packages\MySQLdb\cursors.py", line 179, in execute
    res = self._query(mogrified_query)
          ^^^^^^^^^^^^^^^^^^^^^^^^^^^^
  File "C:\Users\asd\Desktop\소공서버\venv\Lib\site-packages\MySQLdb\cursors.py", line 330, in _query
    db.query(q)
  File "C:\Users\asd\Desktop\소공서버\venv\Lib\site-packages\MySQLdb\connections.py", line 280, in query
    _mysql.connection.query(self, query)
django.db.utils.DataError: (1265, "Data truncated for column 'role' at row 1")
2025-06-21 14:55:23,917 [ERROR] Internal Server Error: /api/project/
Traceback (most recent call last):
  File "C:\Users\asd\Desktop\소공서버\venv\Lib\site-packages\django\db\backends\utils.py", line 105, in _execute
    return self.cursor.execute(sql, params)
           ^^^^^^^^^^^^^^^^^^^^^^^^^^^^^^^^
  File "C:\Users\asd\Desktop\소공서버\venv\Lib\site-packages\django\db\backends\mysql\base.py", line 76, in execute
    return self.cursor.execute(query, args)
           ^^^^^^^^^^^^^^^^^^^^^^^^^^^^^^^^
  File "C:\Users\asd\Desktop\소공서버\venv\Lib\site-packages\MySQLdb\cursors.py", line 179, in execute
    res = self._query(mogrified_query)
          ^^^^^^^^^^^^^^^^^^^^^^^^^^^^
  File "C:\Users\asd\Desktop\소공서버\venv\Lib\site-packages\MySQLdb\cursors.py", line 330, in _query
    db.query(q)
  File "C:\Users\asd\Desktop\소공서버\venv\Lib\site-packages\MySQLdb\connections.py", line 280, in query
    _mysql.connection.query(self, query)
MySQLdb.DataError: (1265, "Data truncated for column 'role' at row 1")

The above exception was the direct cause of the following exception:

Traceback (most recent call last):
  File "C:\Users\asd\Desktop\소공서버\venv\Lib\site-packages\django\core\handlers\exception.py", line 55, in inner
    response = get_response(request)
               ^^^^^^^^^^^^^^^^^^^^^
  File "C:\Users\asd\Desktop\소공서버\venv\Lib\site-packages\django\core\handlers\base.py", line 197, in _get_response
    response = wrapped_callback(request, *callback_args, **callback_kwargs)
               ^^^^^^^^^^^^^^^^^^^^^^^^^^^^^^^^^^^^^^^^^^^^^^^^^^^^^^^^^^^^
  File "C:\Users\asd\Desktop\소공서버\venv\Lib\site-packages\django\views\decorators\csrf.py", line 65, in _view_wrapper
    return view_func(request, *args, **kwargs)
           ^^^^^^^^^^^^^^^^^^^^^^^^^^^^^^^^^^^
  File "C:\Users\asd\Desktop\소공서버\venv\Lib\site-packages\django\views\generic\base.py", line 104, in view
    return self.dispatch(request, *args, **kwargs)
           ^^^^^^^^^^^^^^^^^^^^^^^^^^^^^^^^^^^^^^^
  File "C:\Users\asd\Desktop\소공서버\venv\Lib\site-packages\rest_framework\views.py", line 515, in dispatch
    response = self.handle_exception(exc)
               ^^^^^^^^^^^^^^^^^^^^^^^^^^
  File "C:\Users\asd\Desktop\소공서버\venv\Lib\site-packages\rest_framework\views.py", line 475, in handle_exception
    self.raise_uncaught_exception(exc)
  File "C:\Users\asd\Desktop\소공서버\venv\Lib\site-packages\rest_framework\views.py", line 486, in raise_uncaught_exception
    raise exc
  File "C:\Users\asd\Desktop\소공서버\venv\Lib\site-packages\rest_framework\views.py", line 512, in dispatch
    response = handler(request, *args, **kwargs)
               ^^^^^^^^^^^^^^^^^^^^^^^^^^^^^^^^^
  File "C:\Users\asd\Desktop\CollaborationTool-back\projects\views\create_project_view.py", line 88, in post
    ProjectMember.objects.create(
  File "C:\Users\asd\Desktop\소공서버\venv\Lib\site-packages\django\db\models\manager.py", line 87, in manager_method
    return getattr(self.get_queryset(), name)(*args, **kwargs)
           ^^^^^^^^^^^^^^^^^^^^^^^^^^^^^^^^^^^^^^^^^^^^^^^^^^^
  File "C:\Users\asd\Desktop\소공서버\venv\Lib\site-packages\django\db\models\query.py", line 663, in create
    obj.save(force_insert=True, using=self.db)
  File "C:\Users\asd\Desktop\소공서버\venv\Lib\site-packages\django\db\models\base.py", line 902, in save
    self.save_base(
  File "C:\Users\asd\Desktop\소공서버\venv\Lib\site-packages\django\db\models\base.py", line 1008, in save_base
    updated = self._save_table(
              ^^^^^^^^^^^^^^^^^
  File "C:\Users\asd\Desktop\소공서버\venv\Lib\site-packages\django\db\models\base.py", line 1169, in _save_table
    results = self._do_insert(
              ^^^^^^^^^^^^^^^^
  File "C:\Users\asd\Desktop\소공서버\venv\Lib\site-packages\django\db\models\base.py", line 1210, in _do_insert
    return manager._insert(
           ^^^^^^^^^^^^^^^^
  File "C:\Users\asd\Desktop\소공서버\venv\Lib\site-packages\django\db\models\manager.py", line 87, in manager_method
    return getattr(self.get_queryset(), name)(*args, **kwargs)
           ^^^^^^^^^^^^^^^^^^^^^^^^^^^^^^^^^^^^^^^^^^^^^^^^^^^
  File "C:\Users\asd\Desktop\소공서버\venv\Lib\site-packages\django\db\models\query.py", line 1864, in _insert
    return query.get_compiler(using=using).execute_sql(returning_fields)
           ^^^^^^^^^^^^^^^^^^^^^^^^^^^^^^^^^^^^^^^^^^^^^^^^^^^^^^^^^^^^^
  File "C:\Users\asd\Desktop\소공서버\venv\Lib\site-packages\django\db\models\sql\compiler.py", line 1882, in execute_sql
    cursor.execute(sql, params)
  File "C:\Users\asd\Desktop\소공서버\venv\Lib\site-packages\django\db\backends\utils.py", line 122, in execute
    return super().execute(sql, params)
           ^^^^^^^^^^^^^^^^^^^^^^^^^^^^
  File "C:\Users\asd\Desktop\소공서버\venv\Lib\site-packages\django\db\backends\utils.py", line 79, in execute
    return self._execute_with_wrappers(
           ^^^^^^^^^^^^^^^^^^^^^^^^^^^^
  File "C:\Users\asd\Desktop\소공서버\venv\Lib\site-packages\django\db\backends\utils.py", line 92, in _execute_with_wrappers
    return executor(sql, params, many, context)
           ^^^^^^^^^^^^^^^^^^^^^^^^^^^^^^^^^^^^
  File "C:\Users\asd\Desktop\소공서버\venv\Lib\site-packages\django\db\backends\utils.py", line 100, in _execute
    with self.db.wrap_database_errors:
  File "C:\Users\asd\Desktop\소공서버\venv\Lib\site-packages\django\db\utils.py", line 91, in __exit__
    raise dj_exc_value.with_traceback(traceback) from exc_value
  File "C:\Users\asd\Desktop\소공서버\venv\Lib\site-packages\django\db\backends\utils.py", line 105, in _execute
    return self.cursor.execute(sql, params)
           ^^^^^^^^^^^^^^^^^^^^^^^^^^^^^^^^
  File "C:\Users\asd\Desktop\소공서버\venv\Lib\site-packages\django\db\backends\mysql\base.py", line 76, in execute
    return self.cursor.execute(query, args)
           ^^^^^^^^^^^^^^^^^^^^^^^^^^^^^^^^
  File "C:\Users\asd\Desktop\소공서버\venv\Lib\site-packages\MySQLdb\cursors.py", line 179, in execute
    res = self._query(mogrified_query)
          ^^^^^^^^^^^^^^^^^^^^^^^^^^^^
  File "C:\Users\asd\Desktop\소공서버\venv\Lib\site-packages\MySQLdb\cursors.py", line 330, in _query
    db.query(q)
  File "C:\Users\asd\Desktop\소공서버\venv\Lib\site-packages\MySQLdb\connections.py", line 280, in query
    _mysql.connection.query(self, query)
django.db.utils.DataError: (1265, "Data truncated for column 'role' at row 1")
2025-06-21 14:58:27,019 [INFO] C:\Users\asd\Desktop\CollaborationTool-back\projects\views\create_project_view.py changed, reloading.
2025-06-21 14:58:46,279 [INFO] C:\Users\asd\Desktop\CollaborationTool-back\projects\views\create_project_view.py changed, reloading.
2025-06-21 14:58:53,104 [ERROR] Internal Server Error: /api/project/
Traceback (most recent call last):
  File "C:\Users\asd\Desktop\소공서버\venv\Lib\site-packages\django\db\backends\utils.py", line 105, in _execute
    return self.cursor.execute(sql, params)
           ^^^^^^^^^^^^^^^^^^^^^^^^^^^^^^^^
  File "C:\Users\asd\Desktop\소공서버\venv\Lib\site-packages\django\db\backends\mysql\base.py", line 76, in execute
    return self.cursor.execute(query, args)
           ^^^^^^^^^^^^^^^^^^^^^^^^^^^^^^^^
  File "C:\Users\asd\Desktop\소공서버\venv\Lib\site-packages\MySQLdb\cursors.py", line 179, in execute
    res = self._query(mogrified_query)
          ^^^^^^^^^^^^^^^^^^^^^^^^^^^^
  File "C:\Users\asd\Desktop\소공서버\venv\Lib\site-packages\MySQLdb\cursors.py", line 330, in _query
    db.query(q)
  File "C:\Users\asd\Desktop\소공서버\venv\Lib\site-packages\MySQLdb\connections.py", line 280, in query
    _mysql.connection.query(self, query)
MySQLdb.IntegrityError: (1062, "Duplicate entry '16-aa@test.com' for key 'project_members.PRIMARY'")

The above exception was the direct cause of the following exception:

Traceback (most recent call last):
  File "C:\Users\asd\Desktop\소공서버\venv\Lib\site-packages\django\core\handlers\exception.py", line 55, in inner
    response = get_response(request)
               ^^^^^^^^^^^^^^^^^^^^^
  File "C:\Users\asd\Desktop\소공서버\venv\Lib\site-packages\django\core\handlers\base.py", line 197, in _get_response
    response = wrapped_callback(request, *callback_args, **callback_kwargs)
               ^^^^^^^^^^^^^^^^^^^^^^^^^^^^^^^^^^^^^^^^^^^^^^^^^^^^^^^^^^^^
  File "C:\Users\asd\Desktop\소공서버\venv\Lib\site-packages\django\views\decorators\csrf.py", line 65, in _view_wrapper
    return view_func(request, *args, **kwargs)
           ^^^^^^^^^^^^^^^^^^^^^^^^^^^^^^^^^^^
  File "C:\Users\asd\Desktop\소공서버\venv\Lib\site-packages\django\views\generic\base.py", line 104, in view
    return self.dispatch(request, *args, **kwargs)
           ^^^^^^^^^^^^^^^^^^^^^^^^^^^^^^^^^^^^^^^
  File "C:\Users\asd\Desktop\소공서버\venv\Lib\site-packages\rest_framework\views.py", line 515, in dispatch
    response = self.handle_exception(exc)
               ^^^^^^^^^^^^^^^^^^^^^^^^^^
  File "C:\Users\asd\Desktop\소공서버\venv\Lib\site-packages\rest_framework\views.py", line 475, in handle_exception
    self.raise_uncaught_exception(exc)
  File "C:\Users\asd\Desktop\소공서버\venv\Lib\site-packages\rest_framework\views.py", line 486, in raise_uncaught_exception
    raise exc
  File "C:\Users\asd\Desktop\소공서버\venv\Lib\site-packages\rest_framework\views.py", line 512, in dispatch
    response = handler(request, *args, **kwargs)
               ^^^^^^^^^^^^^^^^^^^^^^^^^^^^^^^^^
  File "C:\Users\asd\Desktop\CollaborationTool-back\projects\views\create_project_view.py", line 91, in post
    ProjectMember.objects.create(
  File "C:\Users\asd\Desktop\소공서버\venv\Lib\site-packages\django\db\models\manager.py", line 87, in manager_method
    return getattr(self.get_queryset(), name)(*args, **kwargs)
           ^^^^^^^^^^^^^^^^^^^^^^^^^^^^^^^^^^^^^^^^^^^^^^^^^^^
  File "C:\Users\asd\Desktop\소공서버\venv\Lib\site-packages\django\db\models\query.py", line 663, in create
    obj.save(force_insert=True, using=self.db)
  File "C:\Users\asd\Desktop\소공서버\venv\Lib\site-packages\django\db\models\base.py", line 902, in save
    self.save_base(
  File "C:\Users\asd\Desktop\소공서버\venv\Lib\site-packages\django\db\models\base.py", line 1008, in save_base
    updated = self._save_table(
              ^^^^^^^^^^^^^^^^^
  File "C:\Users\asd\Desktop\소공서버\venv\Lib\site-packages\django\db\models\base.py", line 1169, in _save_table
    results = self._do_insert(
              ^^^^^^^^^^^^^^^^
  File "C:\Users\asd\Desktop\소공서버\venv\Lib\site-packages\django\db\models\base.py", line 1210, in _do_insert
    return manager._insert(
           ^^^^^^^^^^^^^^^^
  File "C:\Users\asd\Desktop\소공서버\venv\Lib\site-packages\django\db\models\manager.py", line 87, in manager_method
    return getattr(self.get_queryset(), name)(*args, **kwargs)
           ^^^^^^^^^^^^^^^^^^^^^^^^^^^^^^^^^^^^^^^^^^^^^^^^^^^
  File "C:\Users\asd\Desktop\소공서버\venv\Lib\site-packages\django\db\models\query.py", line 1864, in _insert
    return query.get_compiler(using=using).execute_sql(returning_fields)
           ^^^^^^^^^^^^^^^^^^^^^^^^^^^^^^^^^^^^^^^^^^^^^^^^^^^^^^^^^^^^^
  File "C:\Users\asd\Desktop\소공서버\venv\Lib\site-packages\django\db\models\sql\compiler.py", line 1882, in execute_sql
    cursor.execute(sql, params)
  File "C:\Users\asd\Desktop\소공서버\venv\Lib\site-packages\django\db\backends\utils.py", line 122, in execute
    return super().execute(sql, params)
           ^^^^^^^^^^^^^^^^^^^^^^^^^^^^
  File "C:\Users\asd\Desktop\소공서버\venv\Lib\site-packages\django\db\backends\utils.py", line 79, in execute
    return self._execute_with_wrappers(
           ^^^^^^^^^^^^^^^^^^^^^^^^^^^^
  File "C:\Users\asd\Desktop\소공서버\venv\Lib\site-packages\django\db\backends\utils.py", line 92, in _execute_with_wrappers
    return executor(sql, params, many, context)
           ^^^^^^^^^^^^^^^^^^^^^^^^^^^^^^^^^^^^
  File "C:\Users\asd\Desktop\소공서버\venv\Lib\site-packages\django\db\backends\utils.py", line 100, in _execute
    with self.db.wrap_database_errors:
  File "C:\Users\asd\Desktop\소공서버\venv\Lib\site-packages\django\db\utils.py", line 91, in __exit__
    raise dj_exc_value.with_traceback(traceback) from exc_value
  File "C:\Users\asd\Desktop\소공서버\venv\Lib\site-packages\django\db\backends\utils.py", line 105, in _execute
    return self.cursor.execute(sql, params)
           ^^^^^^^^^^^^^^^^^^^^^^^^^^^^^^^^
  File "C:\Users\asd\Desktop\소공서버\venv\Lib\site-packages\django\db\backends\mysql\base.py", line 76, in execute
    return self.cursor.execute(query, args)
           ^^^^^^^^^^^^^^^^^^^^^^^^^^^^^^^^
  File "C:\Users\asd\Desktop\소공서버\venv\Lib\site-packages\MySQLdb\cursors.py", line 179, in execute
    res = self._query(mogrified_query)
          ^^^^^^^^^^^^^^^^^^^^^^^^^^^^
  File "C:\Users\asd\Desktop\소공서버\venv\Lib\site-packages\MySQLdb\cursors.py", line 330, in _query
    db.query(q)
  File "C:\Users\asd\Desktop\소공서버\venv\Lib\site-packages\MySQLdb\connections.py", line 280, in query
    _mysql.connection.query(self, query)
django.db.utils.IntegrityError: (1062, "Duplicate entry '16-aa@test.com' for key 'project_members.PRIMARY'")
2025-06-21 14:59:24,431 [WARNING] Not Found: /api/getprojects
2025-06-21 14:59:24,899 [WARNING] Not Found: /api/getprojects
2025-06-21 14:59:38,027 [WARNING] Not Found: /api/getprojects
2025-06-21 14:59:40,943 [WARNING] Not Found: /api/getprojects
2025-06-21 15:02:24,829 [WARNING] Not Found: /api/getprojects
2025-06-21 15:02:25,720 [WARNING] Not Found: /api/getprojects
2025-06-21 15:02:39,025 [WARNING] Not Found: /api/getprojects
2025-06-21 15:02:41,262 [WARNING] Not Found: /api/getprojects
2025-06-21 15:02:57,664 [WARNING] Not Found: /api/getprojects
2025-06-21 15:03:21,638 [WARNING] Not Found: /api/getprojects
2025-06-21 15:03:22,107 [WARNING] Not Found: /api/getprojects
2025-06-21 15:03:39,609 [WARNING] Not Found: /api/getprojects
2025-06-21 15:08:40,138 [WARNING] Not Found: /api/getprojects
2025-06-21 15:08:41,074 [WARNING] Not Found: /api/getprojects
2025-06-21 15:09:04,830 [WARNING] Not Found: /api/getprojects
2025-06-21 15:09:29,511 [WARNING] Not Found: /api/getprojects
2025-06-21 15:09:29,639 [WARNING] Not Found: /api/getprojects
2025-06-21 15:47:11,964 [INFO] C:\Users\asd\Desktop\CollaborationTool-back\SWE\urls.py changed, reloading.
2025-06-21 15:47:24,935 [INFO] C:\Users\asd\Desktop\CollaborationTool-back\SWE\urls.py changed, reloading.
2025-06-21 15:53:24,128 [INFO] C:\Users\asd\Desktop\CollaborationTool-back\projects\views\project_list_view.py changed, reloading.
2025-06-21 15:54:32,840 [INFO] C:\Users\asd\Desktop\CollaborationTool-back\projects\urls.py changed, reloading.
2025-06-21 15:54:56,770 [WARNING] Not Found: /api/getprojects
2025-06-21 15:54:57,353 [WARNING] Not Found: /api/getprojects
2025-06-21 15:55:04,841 [WARNING] Not Found: /api/getprojects
2025-06-21 15:55:05,020 [WARNING] Not Found: /api/getprojects
2025-06-21 15:55:10,347 [WARNING] Not Found: /api/getprojects
2025-06-21 15:55:10,529 [WARNING] Not Found: /api/getprojects
2025-06-21 15:55:28,807 [WARNING] Not Found: /api/getprojects
2025-06-21 15:55:28,962 [WARNING] Not Found: /api/getprojects
2025-06-21 15:57:03,495 [INFO] C:\Users\asd\Desktop\CollaborationTool-back\SWE\urls.py changed, reloading.
2025-06-21 15:57:19,495 [WARNING] Unauthorized: /api/getprojects/
2025-06-21 15:57:19,922 [WARNING] Unauthorized: /api/getprojects/
2025-06-21 15:58:03,507 [INFO] C:\Users\asd\Desktop\CollaborationTool-back\SWE\urls.py changed, reloading.
2025-06-21 16:21:34,020 [INFO] C:\Users\asd\Desktop\CollaborationTool-back\SWE\urls.py changed, reloading.
2025-06-21 16:21:41,815 [WARNING] Unauthorized: /api/getprojects/
2025-06-21 16:21:42,273 [WARNING] Unauthorized: /api/getprojects/
2025-06-21 16:21:58,670 [WARNING] Unauthorized: /api/getprojects/
2025-06-21 16:21:58,721 [WARNING] Unauthorized: /api/getprojects/
2025-06-21 16:22:35,000 [WARNING] Unauthorized: /api/getprojects/
2025-06-21 16:22:35,429 [WARNING] Unauthorized: /api/getprojects/
2025-06-21 17:14:04,518 [WARNING] Unauthorized: /api/token/
2025-06-21 17:14:09,665 [WARNING] Unauthorized: /api/getprojects/
2025-06-21 17:14:10,106 [WARNING] Unauthorized: /api/getprojects/
2025-06-21 17:18:54,380 [WARNING] Unauthorized: /api/getprojects/
2025-06-21 17:19:38,616 [WARNING] Unauthorized: /api/getprojects/
2025-06-21 17:19:53,712 [WARNING] Unauthorized: /api/getprojects/
2025-06-21 17:19:54,236 [WARNING] Unauthorized: /api/getprojects/
2025-06-21 17:22:07,092 [WARNING] Unauthorized: /api/getprojects/
2025-06-21 17:22:07,533 [WARNING] Unauthorized: /api/getprojects/
2025-06-21 17:23:09,845 [WARNING] Unauthorized: /api/getprojects/
2025-06-21 17:23:10,306 [WARNING] Unauthorized: /api/getprojects/
2025-06-21 17:31:18,692 [WARNING] Not Found: /me
2025-06-21 17:32:22,896 [WARNING] Not Found: /me
2025-06-21 17:33:04,451 [WARNING] Not Found: /me
2025-06-21 17:33:29,386 [WARNING] Not Found: /me
2025-06-21 17:35:18,803 [WARNING] Not Found: /me
2025-06-21 17:41:13,519 [WARNING] Not Found: /me
2025-06-21 17:45:01,869 [WARNING] Not Found: /me
2025-06-21 18:56:05,384 [WARNING] Not Found: /api/tasks/todo/undefined
2025-06-21 18:56:05,387 [WARNING] Not Found: /api/tasks/todo/2
2025-06-21 18:56:05,877 [WARNING] Not Found: /api/tasks/todo/undefined
2025-06-21 18:56:06,078 [WARNING] Not Found: /api/task/card-1
2025-06-21 18:56:09,338 [WARNING] Not Found: /api/task/card-1
2025-06-21 18:56:16,172 [WARNING] Not Found: /api/[object Object]/getmembers
2025-06-21 18:56:23,559 [WARNING] Not Found: /me
2025-06-21 18:56:25,210 [WARNING] Unauthorized: /api/notifications/
2025-06-21 20:46:29,269 [WARNING] Not Found: /api/task/card-2
2025-06-21 20:46:29,271 [WARNING] Not Found: /api/task/card-1
2025-06-21 20:46:29,775 [WARNING] Not Found: /api/task/card-2
2025-06-21 20:46:45,791 [WARNING] Unauthorized: /api/notifications/
2025-06-21 20:55:39,370 [WARNING] Not Found: /api/tasks/todo/3
2025-06-21 20:55:39,375 [WARNING] Not Found: /api/tasks/todo/2
2025-06-21 20:55:39,836 [WARNING] Not Found: /api/tasks/todo/2
2025-06-21 20:55:39,914 [WARNING] Not Found: /api/tasks/todo/2
2025-06-21 20:55:41,259 [WARNING] Not Found: /api/tasks/todo/4
2025-06-21 20:55:54,948 [WARNING] Not Found: /api/tasks/todo/4
2025-06-21 20:55:54,961 [WARNING] Not Found: /api/tasks/todo/2
2025-06-21 20:55:55,017 [WARNING] Not Found: /api/tasks/todo/4
2025-06-21 20:56:18,798 [WARNING] Unauthorized: /api/token/
2025-06-21 20:56:57,891 [WARNING] Not Found: /api/tasks/todo/undefined
2025-06-21 20:56:57,895 [WARNING] Not Found: /api/tasks/todo/2
2025-06-21 20:56:58,444 [WARNING] Not Found: /api/tasks/todo/undefined
2025-06-21 20:58:40,342 [WARNING] Not Found: /me
2025-06-21 20:59:19,073 [WARNING] Unauthorized: /api/notifications/
2025-06-21 20:59:19,079 [WARNING] Unauthorized: /api/notifications/
2025-06-21 21:01:19,837 [WARNING] Unauthorized: /api/notifications/
2025-06-21 21:01:19,855 [WARNING] Unauthorized: /api/notifications/
2025-06-21 21:06:11,903 [WARNING] Not Found: /me
2025-06-21 21:06:12,356 [WARNING] Not Found: /me
2025-06-21 21:06:12,439 [WARNING] Not Found: /me
2025-06-21 21:12:14,556 [WARNING] Unauthorized: /api/getprojects/
2025-06-21 21:12:14,986 [WARNING] Unauthorized: /api/getprojects/
2025-06-21 21:12:28,513 [WARNING] Unauthorized: /api/getprojects/
2025-06-21 21:12:36,136 [WARNING] Unauthorized: /api/getprojects/
2025-06-21 21:12:36,188 [WARNING] Unauthorized: /api/getprojects/
2025-06-21 21:12:45,290 [WARNING] Unauthorized: /api/getprojects/
2025-06-21 21:12:50,985 [WARNING] Not Found: /me
2025-06-21 21:16:51,356 [INFO] C:\Users\asd\Desktop\CollaborationTool-back\SWE\settings.py changed, reloading.
2025-06-21 21:18:47,715 [WARNING] Not Found: /
2025-06-21 21:18:48,314 [WARNING] Not Found: /
2025-06-21 21:18:50,780 [ERROR] Internal Server Error: /api/getprojects/
Traceback (most recent call last):
  File "C:\Users\asd\Desktop\소공서버\venv\Lib\site-packages\django\db\backends\utils.py", line 105, in _execute
    return self.cursor.execute(sql, params)
           ^^^^^^^^^^^^^^^^^^^^^^^^^^^^^^^^
  File "C:\Users\asd\Desktop\소공서버\venv\Lib\site-packages\django\db\backends\mysql\base.py", line 76, in execute
    return self.cursor.execute(query, args)
           ^^^^^^^^^^^^^^^^^^^^^^^^^^^^^^^^
  File "C:\Users\asd\Desktop\소공서버\venv\Lib\site-packages\MySQLdb\cursors.py", line 179, in execute
    res = self._query(mogrified_query)
          ^^^^^^^^^^^^^^^^^^^^^^^^^^^^
  File "C:\Users\asd\Desktop\소공서버\venv\Lib\site-packages\MySQLdb\cursors.py", line 330, in _query
    db.query(q)
  File "C:\Users\asd\Desktop\소공서버\venv\Lib\site-packages\MySQLdb\connections.py", line 280, in query
    _mysql.connection.query(self, query)
MySQLdb.OperationalError: (1054, "Unknown column 'project_members.id' in 'field list'")

The above exception was the direct cause of the following exception:

Traceback (most recent call last):
  File "C:\Users\asd\Desktop\소공서버\venv\Lib\site-packages\django\core\handlers\exception.py", line 55, in inner
    response = get_response(request)
               ^^^^^^^^^^^^^^^^^^^^^
  File "C:\Users\asd\Desktop\소공서버\venv\Lib\site-packages\django\core\handlers\base.py", line 197, in _get_response
    response = wrapped_callback(request, *callback_args, **callback_kwargs)
               ^^^^^^^^^^^^^^^^^^^^^^^^^^^^^^^^^^^^^^^^^^^^^^^^^^^^^^^^^^^^
  File "C:\Users\asd\Desktop\소공서버\venv\Lib\site-packages\django\views\decorators\csrf.py", line 65, in _view_wrapper
    return view_func(request, *args, **kwargs)
           ^^^^^^^^^^^^^^^^^^^^^^^^^^^^^^^^^^^
  File "C:\Users\asd\Desktop\소공서버\venv\Lib\site-packages\django\views\generic\base.py", line 104, in view
    return self.dispatch(request, *args, **kwargs)
           ^^^^^^^^^^^^^^^^^^^^^^^^^^^^^^^^^^^^^^^
  File "C:\Users\asd\Desktop\소공서버\venv\Lib\site-packages\rest_framework\views.py", line 515, in dispatch
    response = self.handle_exception(exc)
               ^^^^^^^^^^^^^^^^^^^^^^^^^^
  File "C:\Users\asd\Desktop\소공서버\venv\Lib\site-packages\rest_framework\views.py", line 475, in handle_exception
    self.raise_uncaught_exception(exc)
  File "C:\Users\asd\Desktop\소공서버\venv\Lib\site-packages\rest_framework\views.py", line 486, in raise_uncaught_exception
    raise exc
  File "C:\Users\asd\Desktop\소공서버\venv\Lib\site-packages\rest_framework\views.py", line 512, in dispatch
    response = handler(request, *args, **kwargs)
               ^^^^^^^^^^^^^^^^^^^^^^^^^^^^^^^^^
  File "C:\Users\asd\Desktop\CollaborationTool-back\projects\views\project_list_view.py", line 16, in get
    result = [
             ^
  File "C:\Users\asd\Desktop\소공서버\venv\Lib\site-packages\django\db\models\query.py", line 384, in __iter__
    self._fetch_all()
  File "C:\Users\asd\Desktop\소공서버\venv\Lib\site-packages\django\db\models\query.py", line 1945, in _fetch_all
    self._result_cache = list(self._iterable_class(self))
                         ^^^^^^^^^^^^^^^^^^^^^^^^^^^^^^^^
  File "C:\Users\asd\Desktop\소공서버\venv\Lib\site-packages\django\db\models\query.py", line 91, in __iter__
    results = compiler.execute_sql(
              ^^^^^^^^^^^^^^^^^^^^^
  File "C:\Users\asd\Desktop\소공서버\venv\Lib\site-packages\django\db\models\sql\compiler.py", line 1623, in execute_sql
    cursor.execute(sql, params)
  File "C:\Users\asd\Desktop\소공서버\venv\Lib\site-packages\django\db\backends\utils.py", line 122, in execute
    return super().execute(sql, params)
           ^^^^^^^^^^^^^^^^^^^^^^^^^^^^
  File "C:\Users\asd\Desktop\소공서버\venv\Lib\site-packages\django\db\backends\utils.py", line 79, in execute
    return self._execute_with_wrappers(
           ^^^^^^^^^^^^^^^^^^^^^^^^^^^^
  File "C:\Users\asd\Desktop\소공서버\venv\Lib\site-packages\django\db\backends\utils.py", line 92, in _execute_with_wrappers
    return executor(sql, params, many, context)
           ^^^^^^^^^^^^^^^^^^^^^^^^^^^^^^^^^^^^
  File "C:\Users\asd\Desktop\소공서버\venv\Lib\site-packages\django\db\backends\utils.py", line 100, in _execute
    with self.db.wrap_database_errors:
  File "C:\Users\asd\Desktop\소공서버\venv\Lib\site-packages\django\db\utils.py", line 91, in __exit__
    raise dj_exc_value.with_traceback(traceback) from exc_value
  File "C:\Users\asd\Desktop\소공서버\venv\Lib\site-packages\django\db\backends\utils.py", line 105, in _execute
    return self.cursor.execute(sql, params)
           ^^^^^^^^^^^^^^^^^^^^^^^^^^^^^^^^
  File "C:\Users\asd\Desktop\소공서버\venv\Lib\site-packages\django\db\backends\mysql\base.py", line 76, in execute
    return self.cursor.execute(query, args)
           ^^^^^^^^^^^^^^^^^^^^^^^^^^^^^^^^
  File "C:\Users\asd\Desktop\소공서버\venv\Lib\site-packages\MySQLdb\cursors.py", line 179, in execute
    res = self._query(mogrified_query)
          ^^^^^^^^^^^^^^^^^^^^^^^^^^^^
  File "C:\Users\asd\Desktop\소공서버\venv\Lib\site-packages\MySQLdb\cursors.py", line 330, in _query
    db.query(q)
  File "C:\Users\asd\Desktop\소공서버\venv\Lib\site-packages\MySQLdb\connections.py", line 280, in query
    _mysql.connection.query(self, query)
django.db.utils.OperationalError: (1054, "Unknown column 'project_members.id' in 'field list'")
2025-06-21 21:18:51,490 [ERROR] Internal Server Error: /api/getprojects/
Traceback (most recent call last):
  File "C:\Users\asd\Desktop\소공서버\venv\Lib\site-packages\django\db\backends\utils.py", line 105, in _execute
    return self.cursor.execute(sql, params)
           ^^^^^^^^^^^^^^^^^^^^^^^^^^^^^^^^
  File "C:\Users\asd\Desktop\소공서버\venv\Lib\site-packages\django\db\backends\mysql\base.py", line 76, in execute
    return self.cursor.execute(query, args)
           ^^^^^^^^^^^^^^^^^^^^^^^^^^^^^^^^
  File "C:\Users\asd\Desktop\소공서버\venv\Lib\site-packages\MySQLdb\cursors.py", line 179, in execute
    res = self._query(mogrified_query)
          ^^^^^^^^^^^^^^^^^^^^^^^^^^^^
  File "C:\Users\asd\Desktop\소공서버\venv\Lib\site-packages\MySQLdb\cursors.py", line 330, in _query
    db.query(q)
  File "C:\Users\asd\Desktop\소공서버\venv\Lib\site-packages\MySQLdb\connections.py", line 280, in query
    _mysql.connection.query(self, query)
MySQLdb.OperationalError: (1054, "Unknown column 'project_members.id' in 'field list'")

The above exception was the direct cause of the following exception:

Traceback (most recent call last):
  File "C:\Users\asd\Desktop\소공서버\venv\Lib\site-packages\django\core\handlers\exception.py", line 55, in inner
    response = get_response(request)
               ^^^^^^^^^^^^^^^^^^^^^
  File "C:\Users\asd\Desktop\소공서버\venv\Lib\site-packages\django\core\handlers\base.py", line 197, in _get_response
    response = wrapped_callback(request, *callback_args, **callback_kwargs)
               ^^^^^^^^^^^^^^^^^^^^^^^^^^^^^^^^^^^^^^^^^^^^^^^^^^^^^^^^^^^^
  File "C:\Users\asd\Desktop\소공서버\venv\Lib\site-packages\django\views\decorators\csrf.py", line 65, in _view_wrapper
    return view_func(request, *args, **kwargs)
           ^^^^^^^^^^^^^^^^^^^^^^^^^^^^^^^^^^^
  File "C:\Users\asd\Desktop\소공서버\venv\Lib\site-packages\django\views\generic\base.py", line 104, in view
    return self.dispatch(request, *args, **kwargs)
           ^^^^^^^^^^^^^^^^^^^^^^^^^^^^^^^^^^^^^^^
  File "C:\Users\asd\Desktop\소공서버\venv\Lib\site-packages\rest_framework\views.py", line 515, in dispatch
    response = self.handle_exception(exc)
               ^^^^^^^^^^^^^^^^^^^^^^^^^^
  File "C:\Users\asd\Desktop\소공서버\venv\Lib\site-packages\rest_framework\views.py", line 475, in handle_exception
    self.raise_uncaught_exception(exc)
  File "C:\Users\asd\Desktop\소공서버\venv\Lib\site-packages\rest_framework\views.py", line 486, in raise_uncaught_exception
    raise exc
  File "C:\Users\asd\Desktop\소공서버\venv\Lib\site-packages\rest_framework\views.py", line 512, in dispatch
    response = handler(request, *args, **kwargs)
               ^^^^^^^^^^^^^^^^^^^^^^^^^^^^^^^^^
  File "C:\Users\asd\Desktop\CollaborationTool-back\projects\views\project_list_view.py", line 16, in get
    result = [
             ^
  File "C:\Users\asd\Desktop\소공서버\venv\Lib\site-packages\django\db\models\query.py", line 384, in __iter__
    self._fetch_all()
  File "C:\Users\asd\Desktop\소공서버\venv\Lib\site-packages\django\db\models\query.py", line 1945, in _fetch_all
    self._result_cache = list(self._iterable_class(self))
                         ^^^^^^^^^^^^^^^^^^^^^^^^^^^^^^^^
  File "C:\Users\asd\Desktop\소공서버\venv\Lib\site-packages\django\db\models\query.py", line 91, in __iter__
    results = compiler.execute_sql(
              ^^^^^^^^^^^^^^^^^^^^^
  File "C:\Users\asd\Desktop\소공서버\venv\Lib\site-packages\django\db\models\sql\compiler.py", line 1623, in execute_sql
    cursor.execute(sql, params)
  File "C:\Users\asd\Desktop\소공서버\venv\Lib\site-packages\django\db\backends\utils.py", line 122, in execute
    return super().execute(sql, params)
           ^^^^^^^^^^^^^^^^^^^^^^^^^^^^
  File "C:\Users\asd\Desktop\소공서버\venv\Lib\site-packages\django\db\backends\utils.py", line 79, in execute
    return self._execute_with_wrappers(
           ^^^^^^^^^^^^^^^^^^^^^^^^^^^^
  File "C:\Users\asd\Desktop\소공서버\venv\Lib\site-packages\django\db\backends\utils.py", line 92, in _execute_with_wrappers
    return executor(sql, params, many, context)
           ^^^^^^^^^^^^^^^^^^^^^^^^^^^^^^^^^^^^
  File "C:\Users\asd\Desktop\소공서버\venv\Lib\site-packages\django\db\backends\utils.py", line 100, in _execute
    with self.db.wrap_database_errors:
  File "C:\Users\asd\Desktop\소공서버\venv\Lib\site-packages\django\db\utils.py", line 91, in __exit__
    raise dj_exc_value.with_traceback(traceback) from exc_value
  File "C:\Users\asd\Desktop\소공서버\venv\Lib\site-packages\django\db\backends\utils.py", line 105, in _execute
    return self.cursor.execute(sql, params)
           ^^^^^^^^^^^^^^^^^^^^^^^^^^^^^^^^
  File "C:\Users\asd\Desktop\소공서버\venv\Lib\site-packages\django\db\backends\mysql\base.py", line 76, in execute
    return self.cursor.execute(query, args)
           ^^^^^^^^^^^^^^^^^^^^^^^^^^^^^^^^
  File "C:\Users\asd\Desktop\소공서버\venv\Lib\site-packages\MySQLdb\cursors.py", line 179, in execute
    res = self._query(mogrified_query)
          ^^^^^^^^^^^^^^^^^^^^^^^^^^^^
  File "C:\Users\asd\Desktop\소공서버\venv\Lib\site-packages\MySQLdb\cursors.py", line 330, in _query
    db.query(q)
  File "C:\Users\asd\Desktop\소공서버\venv\Lib\site-packages\MySQLdb\connections.py", line 280, in query
    _mysql.connection.query(self, query)
django.db.utils.OperationalError: (1054, "Unknown column 'project_members.id' in 'field list'")
2025-06-21 21:20:25,124 [ERROR] Internal Server Error: /api/getprojects/
Traceback (most recent call last):
  File "C:\Users\asd\Desktop\소공서버\venv\Lib\site-packages\django\db\backends\utils.py", line 105, in _execute
    return self.cursor.execute(sql, params)
           ^^^^^^^^^^^^^^^^^^^^^^^^^^^^^^^^
  File "C:\Users\asd\Desktop\소공서버\venv\Lib\site-packages\django\db\backends\mysql\base.py", line 76, in execute
    return self.cursor.execute(query, args)
           ^^^^^^^^^^^^^^^^^^^^^^^^^^^^^^^^
  File "C:\Users\asd\Desktop\소공서버\venv\Lib\site-packages\MySQLdb\cursors.py", line 179, in execute
    res = self._query(mogrified_query)
          ^^^^^^^^^^^^^^^^^^^^^^^^^^^^
  File "C:\Users\asd\Desktop\소공서버\venv\Lib\site-packages\MySQLdb\cursors.py", line 330, in _query
    db.query(q)
  File "C:\Users\asd\Desktop\소공서버\venv\Lib\site-packages\MySQLdb\connections.py", line 280, in query
    _mysql.connection.query(self, query)
MySQLdb.OperationalError: (1054, "Unknown column 'project_members.id' in 'field list'")

The above exception was the direct cause of the following exception:

Traceback (most recent call last):
  File "C:\Users\asd\Desktop\소공서버\venv\Lib\site-packages\django\core\handlers\exception.py", line 55, in inner
    response = get_response(request)
               ^^^^^^^^^^^^^^^^^^^^^
  File "C:\Users\asd\Desktop\소공서버\venv\Lib\site-packages\django\core\handlers\base.py", line 197, in _get_response
    response = wrapped_callback(request, *callback_args, **callback_kwargs)
               ^^^^^^^^^^^^^^^^^^^^^^^^^^^^^^^^^^^^^^^^^^^^^^^^^^^^^^^^^^^^
  File "C:\Users\asd\Desktop\소공서버\venv\Lib\site-packages\django\views\decorators\csrf.py", line 65, in _view_wrapper
    return view_func(request, *args, **kwargs)
           ^^^^^^^^^^^^^^^^^^^^^^^^^^^^^^^^^^^
  File "C:\Users\asd\Desktop\소공서버\venv\Lib\site-packages\django\views\generic\base.py", line 104, in view
    return self.dispatch(request, *args, **kwargs)
           ^^^^^^^^^^^^^^^^^^^^^^^^^^^^^^^^^^^^^^^
  File "C:\Users\asd\Desktop\소공서버\venv\Lib\site-packages\rest_framework\views.py", line 515, in dispatch
    response = self.handle_exception(exc)
               ^^^^^^^^^^^^^^^^^^^^^^^^^^
  File "C:\Users\asd\Desktop\소공서버\venv\Lib\site-packages\rest_framework\views.py", line 475, in handle_exception
    self.raise_uncaught_exception(exc)
  File "C:\Users\asd\Desktop\소공서버\venv\Lib\site-packages\rest_framework\views.py", line 486, in raise_uncaught_exception
    raise exc
  File "C:\Users\asd\Desktop\소공서버\venv\Lib\site-packages\rest_framework\views.py", line 512, in dispatch
    response = handler(request, *args, **kwargs)
               ^^^^^^^^^^^^^^^^^^^^^^^^^^^^^^^^^
  File "C:\Users\asd\Desktop\CollaborationTool-back\projects\views\project_list_view.py", line 16, in get
    result = [
             ^
  File "C:\Users\asd\Desktop\소공서버\venv\Lib\site-packages\django\db\models\query.py", line 384, in __iter__
    self._fetch_all()
  File "C:\Users\asd\Desktop\소공서버\venv\Lib\site-packages\django\db\models\query.py", line 1945, in _fetch_all
    self._result_cache = list(self._iterable_class(self))
                         ^^^^^^^^^^^^^^^^^^^^^^^^^^^^^^^^
  File "C:\Users\asd\Desktop\소공서버\venv\Lib\site-packages\django\db\models\query.py", line 91, in __iter__
    results = compiler.execute_sql(
              ^^^^^^^^^^^^^^^^^^^^^
  File "C:\Users\asd\Desktop\소공서버\venv\Lib\site-packages\django\db\models\sql\compiler.py", line 1623, in execute_sql
    cursor.execute(sql, params)
  File "C:\Users\asd\Desktop\소공서버\venv\Lib\site-packages\django\db\backends\utils.py", line 122, in execute
    return super().execute(sql, params)
           ^^^^^^^^^^^^^^^^^^^^^^^^^^^^
  File "C:\Users\asd\Desktop\소공서버\venv\Lib\site-packages\django\db\backends\utils.py", line 79, in execute
    return self._execute_with_wrappers(
           ^^^^^^^^^^^^^^^^^^^^^^^^^^^^
  File "C:\Users\asd\Desktop\소공서버\venv\Lib\site-packages\django\db\backends\utils.py", line 92, in _execute_with_wrappers
    return executor(sql, params, many, context)
           ^^^^^^^^^^^^^^^^^^^^^^^^^^^^^^^^^^^^
  File "C:\Users\asd\Desktop\소공서버\venv\Lib\site-packages\django\db\backends\utils.py", line 100, in _execute
    with self.db.wrap_database_errors:
  File "C:\Users\asd\Desktop\소공서버\venv\Lib\site-packages\django\db\utils.py", line 91, in __exit__
    raise dj_exc_value.with_traceback(traceback) from exc_value
  File "C:\Users\asd\Desktop\소공서버\venv\Lib\site-packages\django\db\backends\utils.py", line 105, in _execute
    return self.cursor.execute(sql, params)
           ^^^^^^^^^^^^^^^^^^^^^^^^^^^^^^^^
  File "C:\Users\asd\Desktop\소공서버\venv\Lib\site-packages\django\db\backends\mysql\base.py", line 76, in execute
    return self.cursor.execute(query, args)
           ^^^^^^^^^^^^^^^^^^^^^^^^^^^^^^^^
  File "C:\Users\asd\Desktop\소공서버\venv\Lib\site-packages\MySQLdb\cursors.py", line 179, in execute
    res = self._query(mogrified_query)
          ^^^^^^^^^^^^^^^^^^^^^^^^^^^^
  File "C:\Users\asd\Desktop\소공서버\venv\Lib\site-packages\MySQLdb\cursors.py", line 330, in _query
    db.query(q)
  File "C:\Users\asd\Desktop\소공서버\venv\Lib\site-packages\MySQLdb\connections.py", line 280, in query
    _mysql.connection.query(self, query)
django.db.utils.OperationalError: (1054, "Unknown column 'project_members.id' in 'field list'")
2025-06-21 21:20:25,853 [ERROR] Internal Server Error: /api/getprojects/
Traceback (most recent call last):
  File "C:\Users\asd\Desktop\소공서버\venv\Lib\site-packages\django\db\backends\utils.py", line 105, in _execute
    return self.cursor.execute(sql, params)
           ^^^^^^^^^^^^^^^^^^^^^^^^^^^^^^^^
  File "C:\Users\asd\Desktop\소공서버\venv\Lib\site-packages\django\db\backends\mysql\base.py", line 76, in execute
    return self.cursor.execute(query, args)
           ^^^^^^^^^^^^^^^^^^^^^^^^^^^^^^^^
  File "C:\Users\asd\Desktop\소공서버\venv\Lib\site-packages\MySQLdb\cursors.py", line 179, in execute
    res = self._query(mogrified_query)
          ^^^^^^^^^^^^^^^^^^^^^^^^^^^^
  File "C:\Users\asd\Desktop\소공서버\venv\Lib\site-packages\MySQLdb\cursors.py", line 330, in _query
    db.query(q)
  File "C:\Users\asd\Desktop\소공서버\venv\Lib\site-packages\MySQLdb\connections.py", line 280, in query
    _mysql.connection.query(self, query)
MySQLdb.OperationalError: (1054, "Unknown column 'project_members.id' in 'field list'")

The above exception was the direct cause of the following exception:

Traceback (most recent call last):
  File "C:\Users\asd\Desktop\소공서버\venv\Lib\site-packages\django\core\handlers\exception.py", line 55, in inner
    response = get_response(request)
               ^^^^^^^^^^^^^^^^^^^^^
  File "C:\Users\asd\Desktop\소공서버\venv\Lib\site-packages\django\core\handlers\base.py", line 197, in _get_response
    response = wrapped_callback(request, *callback_args, **callback_kwargs)
               ^^^^^^^^^^^^^^^^^^^^^^^^^^^^^^^^^^^^^^^^^^^^^^^^^^^^^^^^^^^^
  File "C:\Users\asd\Desktop\소공서버\venv\Lib\site-packages\django\views\decorators\csrf.py", line 65, in _view_wrapper
    return view_func(request, *args, **kwargs)
           ^^^^^^^^^^^^^^^^^^^^^^^^^^^^^^^^^^^
  File "C:\Users\asd\Desktop\소공서버\venv\Lib\site-packages\django\views\generic\base.py", line 104, in view
    return self.dispatch(request, *args, **kwargs)
           ^^^^^^^^^^^^^^^^^^^^^^^^^^^^^^^^^^^^^^^
  File "C:\Users\asd\Desktop\소공서버\venv\Lib\site-packages\rest_framework\views.py", line 515, in dispatch
    response = self.handle_exception(exc)
               ^^^^^^^^^^^^^^^^^^^^^^^^^^
  File "C:\Users\asd\Desktop\소공서버\venv\Lib\site-packages\rest_framework\views.py", line 475, in handle_exception
    self.raise_uncaught_exception(exc)
  File "C:\Users\asd\Desktop\소공서버\venv\Lib\site-packages\rest_framework\views.py", line 486, in raise_uncaught_exception
    raise exc
  File "C:\Users\asd\Desktop\소공서버\venv\Lib\site-packages\rest_framework\views.py", line 512, in dispatch
    response = handler(request, *args, **kwargs)
               ^^^^^^^^^^^^^^^^^^^^^^^^^^^^^^^^^
  File "C:\Users\asd\Desktop\CollaborationTool-back\projects\views\project_list_view.py", line 16, in get
    result = [
             ^
  File "C:\Users\asd\Desktop\소공서버\venv\Lib\site-packages\django\db\models\query.py", line 384, in __iter__
    self._fetch_all()
  File "C:\Users\asd\Desktop\소공서버\venv\Lib\site-packages\django\db\models\query.py", line 1945, in _fetch_all
    self._result_cache = list(self._iterable_class(self))
                         ^^^^^^^^^^^^^^^^^^^^^^^^^^^^^^^^
  File "C:\Users\asd\Desktop\소공서버\venv\Lib\site-packages\django\db\models\query.py", line 91, in __iter__
    results = compiler.execute_sql(
              ^^^^^^^^^^^^^^^^^^^^^
  File "C:\Users\asd\Desktop\소공서버\venv\Lib\site-packages\django\db\models\sql\compiler.py", line 1623, in execute_sql
    cursor.execute(sql, params)
  File "C:\Users\asd\Desktop\소공서버\venv\Lib\site-packages\django\db\backends\utils.py", line 122, in execute
    return super().execute(sql, params)
           ^^^^^^^^^^^^^^^^^^^^^^^^^^^^
  File "C:\Users\asd\Desktop\소공서버\venv\Lib\site-packages\django\db\backends\utils.py", line 79, in execute
    return self._execute_with_wrappers(
           ^^^^^^^^^^^^^^^^^^^^^^^^^^^^
  File "C:\Users\asd\Desktop\소공서버\venv\Lib\site-packages\django\db\backends\utils.py", line 92, in _execute_with_wrappers
    return executor(sql, params, many, context)
           ^^^^^^^^^^^^^^^^^^^^^^^^^^^^^^^^^^^^
  File "C:\Users\asd\Desktop\소공서버\venv\Lib\site-packages\django\db\backends\utils.py", line 100, in _execute
    with self.db.wrap_database_errors:
  File "C:\Users\asd\Desktop\소공서버\venv\Lib\site-packages\django\db\utils.py", line 91, in __exit__
    raise dj_exc_value.with_traceback(traceback) from exc_value
  File "C:\Users\asd\Desktop\소공서버\venv\Lib\site-packages\django\db\backends\utils.py", line 105, in _execute
    return self.cursor.execute(sql, params)
           ^^^^^^^^^^^^^^^^^^^^^^^^^^^^^^^^
  File "C:\Users\asd\Desktop\소공서버\venv\Lib\site-packages\django\db\backends\mysql\base.py", line 76, in execute
    return self.cursor.execute(query, args)
           ^^^^^^^^^^^^^^^^^^^^^^^^^^^^^^^^
  File "C:\Users\asd\Desktop\소공서버\venv\Lib\site-packages\MySQLdb\cursors.py", line 179, in execute
    res = self._query(mogrified_query)
          ^^^^^^^^^^^^^^^^^^^^^^^^^^^^
  File "C:\Users\asd\Desktop\소공서버\venv\Lib\site-packages\MySQLdb\cursors.py", line 330, in _query
    db.query(q)
  File "C:\Users\asd\Desktop\소공서버\venv\Lib\site-packages\MySQLdb\connections.py", line 280, in query
    _mysql.connection.query(self, query)
django.db.utils.OperationalError: (1054, "Unknown column 'project_members.id' in 'field list'")
2025-06-21 21:21:20,319 [WARNING] Not Found: /
2025-06-21 21:22:42,256 [WARNING] Not Found: /api/tasks/todo/undefined
2025-06-21 21:22:42,262 [WARNING] Not Found: /api/tasks/todo/3
2025-06-21 21:22:42,264 [WARNING] Not Found: /api/tasks/todo/2
2025-06-21 21:22:42,895 [WARNING] Not Found: /api/tasks/todo/undefined
2025-06-21 21:22:52,198 [ERROR] Internal Server Error: /api/getprojects
Traceback (most recent call last):
  File "C:\Users\asd\Desktop\소공서버\venv\Lib\site-packages\django\core\handlers\exception.py", line 55, in inner
    response = get_response(request)
               ^^^^^^^^^^^^^^^^^^^^^
  File "C:\Users\asd\Desktop\소공서버\venv\Lib\site-packages\django\utils\deprecation.py", line 122, in __call__
    response = self.process_response(request, response)
               ^^^^^^^^^^^^^^^^^^^^^^^^^^^^^^^^^^^^^^^^
  File "C:\Users\asd\Desktop\소공서버\venv\Lib\site-packages\django\middleware\common.py", line 108, in process_response
    return self.response_redirect_class(self.get_full_path_with_slash(request))
                                        ^^^^^^^^^^^^^^^^^^^^^^^^^^^^^^^^^^^^^^
  File "C:\Users\asd\Desktop\소공서버\venv\Lib\site-packages\django\middleware\common.py", line 87, in get_full_path_with_slash
    raise RuntimeError(
RuntimeError: You called this URL via POST, but the URL doesn't end in a slash and you have APPEND_SLASH set. Django can't redirect to the slash URL while maintaining POST data. Change your form to point to projects-usb-reviewer-right.trycloudflare.com/api/getprojects/ (note the trailing slash), or set APPEND_SLASH=False in your Django settings.
2025-06-21 21:23:08,911 [ERROR] Internal Server Error: /api/getprojects
Traceback (most recent call last):
  File "C:\Users\asd\Desktop\소공서버\venv\Lib\site-packages\django\core\handlers\exception.py", line 55, in inner
    response = get_response(request)
               ^^^^^^^^^^^^^^^^^^^^^
  File "C:\Users\asd\Desktop\소공서버\venv\Lib\site-packages\django\utils\deprecation.py", line 122, in __call__
    response = self.process_response(request, response)
               ^^^^^^^^^^^^^^^^^^^^^^^^^^^^^^^^^^^^^^^^
  File "C:\Users\asd\Desktop\소공서버\venv\Lib\site-packages\django\middleware\common.py", line 108, in process_response
    return self.response_redirect_class(self.get_full_path_with_slash(request))
                                        ^^^^^^^^^^^^^^^^^^^^^^^^^^^^^^^^^^^^^^
  File "C:\Users\asd\Desktop\소공서버\venv\Lib\site-packages\django\middleware\common.py", line 87, in get_full_path_with_slash
    raise RuntimeError(
RuntimeError: You called this URL via POST, but the URL doesn't end in a slash and you have APPEND_SLASH set. Django can't redirect to the slash URL while maintaining POST data. Change your form to point to projects-usb-reviewer-right.trycloudflare.com/api/getprojects/ (note the trailing slash), or set APPEND_SLASH=False in your Django settings.
2025-06-21 21:23:20,842 [ERROR] Internal Server Error: /api/getprojects
Traceback (most recent call last):
  File "C:\Users\asd\Desktop\소공서버\venv\Lib\site-packages\django\core\handlers\exception.py", line 55, in inner
    response = get_response(request)
               ^^^^^^^^^^^^^^^^^^^^^
  File "C:\Users\asd\Desktop\소공서버\venv\Lib\site-packages\django\utils\deprecation.py", line 122, in __call__
    response = self.process_response(request, response)
               ^^^^^^^^^^^^^^^^^^^^^^^^^^^^^^^^^^^^^^^^
  File "C:\Users\asd\Desktop\소공서버\venv\Lib\site-packages\django\middleware\common.py", line 108, in process_response
    return self.response_redirect_class(self.get_full_path_with_slash(request))
                                        ^^^^^^^^^^^^^^^^^^^^^^^^^^^^^^^^^^^^^^
  File "C:\Users\asd\Desktop\소공서버\venv\Lib\site-packages\django\middleware\common.py", line 87, in get_full_path_with_slash
    raise RuntimeError(
RuntimeError: You called this URL via POST, but the URL doesn't end in a slash and you have APPEND_SLASH set. Django can't redirect to the slash URL while maintaining POST data. Change your form to point to projects-usb-reviewer-right.trycloudflare.com/api/getprojects/ (note the trailing slash), or set APPEND_SLASH=False in your Django settings.
2025-06-21 21:24:10,114 [ERROR] Internal Server Error: /api/getprojects/
Traceback (most recent call last):
  File "C:\Users\asd\Desktop\소공서버\venv\Lib\site-packages\django\db\backends\utils.py", line 105, in _execute
    return self.cursor.execute(sql, params)
           ^^^^^^^^^^^^^^^^^^^^^^^^^^^^^^^^
  File "C:\Users\asd\Desktop\소공서버\venv\Lib\site-packages\django\db\backends\mysql\base.py", line 76, in execute
    return self.cursor.execute(query, args)
           ^^^^^^^^^^^^^^^^^^^^^^^^^^^^^^^^
  File "C:\Users\asd\Desktop\소공서버\venv\Lib\site-packages\MySQLdb\cursors.py", line 179, in execute
    res = self._query(mogrified_query)
          ^^^^^^^^^^^^^^^^^^^^^^^^^^^^
  File "C:\Users\asd\Desktop\소공서버\venv\Lib\site-packages\MySQLdb\cursors.py", line 330, in _query
    db.query(q)
  File "C:\Users\asd\Desktop\소공서버\venv\Lib\site-packages\MySQLdb\connections.py", line 280, in query
    _mysql.connection.query(self, query)
MySQLdb.OperationalError: (1054, "Unknown column 'project_members.id' in 'field list'")

The above exception was the direct cause of the following exception:

Traceback (most recent call last):
  File "C:\Users\asd\Desktop\소공서버\venv\Lib\site-packages\django\core\handlers\exception.py", line 55, in inner
    response = get_response(request)
               ^^^^^^^^^^^^^^^^^^^^^
  File "C:\Users\asd\Desktop\소공서버\venv\Lib\site-packages\django\core\handlers\base.py", line 197, in _get_response
    response = wrapped_callback(request, *callback_args, **callback_kwargs)
               ^^^^^^^^^^^^^^^^^^^^^^^^^^^^^^^^^^^^^^^^^^^^^^^^^^^^^^^^^^^^
  File "C:\Users\asd\Desktop\소공서버\venv\Lib\site-packages\django\views\decorators\csrf.py", line 65, in _view_wrapper
    return view_func(request, *args, **kwargs)
           ^^^^^^^^^^^^^^^^^^^^^^^^^^^^^^^^^^^
  File "C:\Users\asd\Desktop\소공서버\venv\Lib\site-packages\django\views\generic\base.py", line 104, in view
    return self.dispatch(request, *args, **kwargs)
           ^^^^^^^^^^^^^^^^^^^^^^^^^^^^^^^^^^^^^^^
  File "C:\Users\asd\Desktop\소공서버\venv\Lib\site-packages\rest_framework\views.py", line 515, in dispatch
    response = self.handle_exception(exc)
               ^^^^^^^^^^^^^^^^^^^^^^^^^^
  File "C:\Users\asd\Desktop\소공서버\venv\Lib\site-packages\rest_framework\views.py", line 475, in handle_exception
    self.raise_uncaught_exception(exc)
  File "C:\Users\asd\Desktop\소공서버\venv\Lib\site-packages\rest_framework\views.py", line 486, in raise_uncaught_exception
    raise exc
  File "C:\Users\asd\Desktop\소공서버\venv\Lib\site-packages\rest_framework\views.py", line 512, in dispatch
    response = handler(request, *args, **kwargs)
               ^^^^^^^^^^^^^^^^^^^^^^^^^^^^^^^^^
  File "C:\Users\asd\Desktop\CollaborationTool-back\projects\views\project_list_view.py", line 16, in get
    result = [
             ^
  File "C:\Users\asd\Desktop\소공서버\venv\Lib\site-packages\django\db\models\query.py", line 384, in __iter__
    self._fetch_all()
  File "C:\Users\asd\Desktop\소공서버\venv\Lib\site-packages\django\db\models\query.py", line 1945, in _fetch_all
    self._result_cache = list(self._iterable_class(self))
                         ^^^^^^^^^^^^^^^^^^^^^^^^^^^^^^^^
  File "C:\Users\asd\Desktop\소공서버\venv\Lib\site-packages\django\db\models\query.py", line 91, in __iter__
    results = compiler.execute_sql(
              ^^^^^^^^^^^^^^^^^^^^^
  File "C:\Users\asd\Desktop\소공서버\venv\Lib\site-packages\django\db\models\sql\compiler.py", line 1623, in execute_sql
    cursor.execute(sql, params)
  File "C:\Users\asd\Desktop\소공서버\venv\Lib\site-packages\django\db\backends\utils.py", line 122, in execute
    return super().execute(sql, params)
           ^^^^^^^^^^^^^^^^^^^^^^^^^^^^
  File "C:\Users\asd\Desktop\소공서버\venv\Lib\site-packages\django\db\backends\utils.py", line 79, in execute
    return self._execute_with_wrappers(
           ^^^^^^^^^^^^^^^^^^^^^^^^^^^^
  File "C:\Users\asd\Desktop\소공서버\venv\Lib\site-packages\django\db\backends\utils.py", line 92, in _execute_with_wrappers
    return executor(sql, params, many, context)
           ^^^^^^^^^^^^^^^^^^^^^^^^^^^^^^^^^^^^
  File "C:\Users\asd\Desktop\소공서버\venv\Lib\site-packages\django\db\backends\utils.py", line 100, in _execute
    with self.db.wrap_database_errors:
  File "C:\Users\asd\Desktop\소공서버\venv\Lib\site-packages\django\db\utils.py", line 91, in __exit__
    raise dj_exc_value.with_traceback(traceback) from exc_value
  File "C:\Users\asd\Desktop\소공서버\venv\Lib\site-packages\django\db\backends\utils.py", line 105, in _execute
    return self.cursor.execute(sql, params)
           ^^^^^^^^^^^^^^^^^^^^^^^^^^^^^^^^
  File "C:\Users\asd\Desktop\소공서버\venv\Lib\site-packages\django\db\backends\mysql\base.py", line 76, in execute
    return self.cursor.execute(query, args)
           ^^^^^^^^^^^^^^^^^^^^^^^^^^^^^^^^
  File "C:\Users\asd\Desktop\소공서버\venv\Lib\site-packages\MySQLdb\cursors.py", line 179, in execute
    res = self._query(mogrified_query)
          ^^^^^^^^^^^^^^^^^^^^^^^^^^^^
  File "C:\Users\asd\Desktop\소공서버\venv\Lib\site-packages\MySQLdb\cursors.py", line 330, in _query
    db.query(q)
  File "C:\Users\asd\Desktop\소공서버\venv\Lib\site-packages\MySQLdb\connections.py", line 280, in query
    _mysql.connection.query(self, query)
django.db.utils.OperationalError: (1054, "Unknown column 'project_members.id' in 'field list'")
2025-06-21 21:24:46,406 [ERROR] Internal Server Error: /api/getprojects/
Traceback (most recent call last):
  File "C:\Users\asd\Desktop\소공서버\venv\Lib\site-packages\django\db\backends\utils.py", line 105, in _execute
    return self.cursor.execute(sql, params)
           ^^^^^^^^^^^^^^^^^^^^^^^^^^^^^^^^
  File "C:\Users\asd\Desktop\소공서버\venv\Lib\site-packages\django\db\backends\mysql\base.py", line 76, in execute
    return self.cursor.execute(query, args)
           ^^^^^^^^^^^^^^^^^^^^^^^^^^^^^^^^
  File "C:\Users\asd\Desktop\소공서버\venv\Lib\site-packages\MySQLdb\cursors.py", line 179, in execute
    res = self._query(mogrified_query)
          ^^^^^^^^^^^^^^^^^^^^^^^^^^^^
  File "C:\Users\asd\Desktop\소공서버\venv\Lib\site-packages\MySQLdb\cursors.py", line 330, in _query
    db.query(q)
  File "C:\Users\asd\Desktop\소공서버\venv\Lib\site-packages\MySQLdb\connections.py", line 280, in query
    _mysql.connection.query(self, query)
MySQLdb.OperationalError: (1054, "Unknown column 'project_members.id' in 'field list'")

The above exception was the direct cause of the following exception:

Traceback (most recent call last):
  File "C:\Users\asd\Desktop\소공서버\venv\Lib\site-packages\django\core\handlers\exception.py", line 55, in inner
    response = get_response(request)
               ^^^^^^^^^^^^^^^^^^^^^
  File "C:\Users\asd\Desktop\소공서버\venv\Lib\site-packages\django\core\handlers\base.py", line 197, in _get_response
    response = wrapped_callback(request, *callback_args, **callback_kwargs)
               ^^^^^^^^^^^^^^^^^^^^^^^^^^^^^^^^^^^^^^^^^^^^^^^^^^^^^^^^^^^^
  File "C:\Users\asd\Desktop\소공서버\venv\Lib\site-packages\django\views\decorators\csrf.py", line 65, in _view_wrapper
    return view_func(request, *args, **kwargs)
           ^^^^^^^^^^^^^^^^^^^^^^^^^^^^^^^^^^^
  File "C:\Users\asd\Desktop\소공서버\venv\Lib\site-packages\django\views\generic\base.py", line 104, in view
    return self.dispatch(request, *args, **kwargs)
           ^^^^^^^^^^^^^^^^^^^^^^^^^^^^^^^^^^^^^^^
  File "C:\Users\asd\Desktop\소공서버\venv\Lib\site-packages\rest_framework\views.py", line 515, in dispatch
    response = self.handle_exception(exc)
               ^^^^^^^^^^^^^^^^^^^^^^^^^^
  File "C:\Users\asd\Desktop\소공서버\venv\Lib\site-packages\rest_framework\views.py", line 475, in handle_exception
    self.raise_uncaught_exception(exc)
  File "C:\Users\asd\Desktop\소공서버\venv\Lib\site-packages\rest_framework\views.py", line 486, in raise_uncaught_exception
    raise exc
  File "C:\Users\asd\Desktop\소공서버\venv\Lib\site-packages\rest_framework\views.py", line 512, in dispatch
    response = handler(request, *args, **kwargs)
               ^^^^^^^^^^^^^^^^^^^^^^^^^^^^^^^^^
  File "C:\Users\asd\Desktop\CollaborationTool-back\projects\views\project_list_view.py", line 16, in get
    result = [
             ^
  File "C:\Users\asd\Desktop\소공서버\venv\Lib\site-packages\django\db\models\query.py", line 384, in __iter__
    self._fetch_all()
  File "C:\Users\asd\Desktop\소공서버\venv\Lib\site-packages\django\db\models\query.py", line 1945, in _fetch_all
    self._result_cache = list(self._iterable_class(self))
                         ^^^^^^^^^^^^^^^^^^^^^^^^^^^^^^^^
  File "C:\Users\asd\Desktop\소공서버\venv\Lib\site-packages\django\db\models\query.py", line 91, in __iter__
    results = compiler.execute_sql(
              ^^^^^^^^^^^^^^^^^^^^^
  File "C:\Users\asd\Desktop\소공서버\venv\Lib\site-packages\django\db\models\sql\compiler.py", line 1623, in execute_sql
    cursor.execute(sql, params)
  File "C:\Users\asd\Desktop\소공서버\venv\Lib\site-packages\django\db\backends\utils.py", line 122, in execute
    return super().execute(sql, params)
           ^^^^^^^^^^^^^^^^^^^^^^^^^^^^
  File "C:\Users\asd\Desktop\소공서버\venv\Lib\site-packages\django\db\backends\utils.py", line 79, in execute
    return self._execute_with_wrappers(
           ^^^^^^^^^^^^^^^^^^^^^^^^^^^^
  File "C:\Users\asd\Desktop\소공서버\venv\Lib\site-packages\django\db\backends\utils.py", line 92, in _execute_with_wrappers
    return executor(sql, params, many, context)
           ^^^^^^^^^^^^^^^^^^^^^^^^^^^^^^^^^^^^
  File "C:\Users\asd\Desktop\소공서버\venv\Lib\site-packages\django\db\backends\utils.py", line 100, in _execute
    with self.db.wrap_database_errors:
  File "C:\Users\asd\Desktop\소공서버\venv\Lib\site-packages\django\db\utils.py", line 91, in __exit__
    raise dj_exc_value.with_traceback(traceback) from exc_value
  File "C:\Users\asd\Desktop\소공서버\venv\Lib\site-packages\django\db\backends\utils.py", line 105, in _execute
    return self.cursor.execute(sql, params)
           ^^^^^^^^^^^^^^^^^^^^^^^^^^^^^^^^
  File "C:\Users\asd\Desktop\소공서버\venv\Lib\site-packages\django\db\backends\mysql\base.py", line 76, in execute
    return self.cursor.execute(query, args)
           ^^^^^^^^^^^^^^^^^^^^^^^^^^^^^^^^
  File "C:\Users\asd\Desktop\소공서버\venv\Lib\site-packages\MySQLdb\cursors.py", line 179, in execute
    res = self._query(mogrified_query)
          ^^^^^^^^^^^^^^^^^^^^^^^^^^^^
  File "C:\Users\asd\Desktop\소공서버\venv\Lib\site-packages\MySQLdb\cursors.py", line 330, in _query
    db.query(q)
  File "C:\Users\asd\Desktop\소공서버\venv\Lib\site-packages\MySQLdb\connections.py", line 280, in query
    _mysql.connection.query(self, query)
django.db.utils.OperationalError: (1054, "Unknown column 'project_members.id' in 'field list'")
2025-06-21 21:24:50,066 [WARNING] Not Found: /
2025-06-21 21:28:48,787 [WARNING] Unauthorized: /projects/getprojects/
2025-06-21 21:28:49,423 [WARNING] Unauthorized: /projects/getprojects/
2025-06-21 21:28:49,681 [WARNING] Unauthorized: /api/emailcheck/
2025-06-21 21:29:04,476 [WARNING] Unauthorized: /api/project/
2025-06-21 21:29:08,618 [WARNING] Unauthorized: /api/project/
2025-06-21 21:29:13,880 [WARNING] Unauthorized: /api/emailcheck/
2025-06-21 21:29:53,795 [WARNING] Unauthorized: /projects/getprojects/
2025-06-21 21:29:54,248 [WARNING] Unauthorized: /projects/getprojects/
2025-06-21 21:30:11,236 [WARNING] Unauthorized: /projects/getprojects/
2025-06-21 21:30:11,329 [WARNING] Unauthorized: /projects/getprojects/
2025-06-21 21:30:29,352 [WARNING] Unauthorized: /projects/getprojects/
2025-06-21 21:40:12,777 [WARNING] Unauthorized: /api/getprojects/
2025-06-21 21:40:37,429 [ERROR] Internal Server Error: /api/getprojects/
Traceback (most recent call last):
  File "C:\Users\asd\Desktop\소공서버\venv\Lib\site-packages\django\db\backends\utils.py", line 105, in _execute
    return self.cursor.execute(sql, params)
           ^^^^^^^^^^^^^^^^^^^^^^^^^^^^^^^^
  File "C:\Users\asd\Desktop\소공서버\venv\Lib\site-packages\django\db\backends\mysql\base.py", line 76, in execute
    return self.cursor.execute(query, args)
           ^^^^^^^^^^^^^^^^^^^^^^^^^^^^^^^^
  File "C:\Users\asd\Desktop\소공서버\venv\Lib\site-packages\MySQLdb\cursors.py", line 179, in execute
    res = self._query(mogrified_query)
          ^^^^^^^^^^^^^^^^^^^^^^^^^^^^
  File "C:\Users\asd\Desktop\소공서버\venv\Lib\site-packages\MySQLdb\cursors.py", line 330, in _query
    db.query(q)
  File "C:\Users\asd\Desktop\소공서버\venv\Lib\site-packages\MySQLdb\connections.py", line 280, in query
    _mysql.connection.query(self, query)
MySQLdb.OperationalError: (1054, "Unknown column 'project_members.id' in 'field list'")

The above exception was the direct cause of the following exception:

Traceback (most recent call last):
  File "C:\Users\asd\Desktop\소공서버\venv\Lib\site-packages\django\core\handlers\exception.py", line 55, in inner
    response = get_response(request)
               ^^^^^^^^^^^^^^^^^^^^^
  File "C:\Users\asd\Desktop\소공서버\venv\Lib\site-packages\django\core\handlers\base.py", line 197, in _get_response
    response = wrapped_callback(request, *callback_args, **callback_kwargs)
               ^^^^^^^^^^^^^^^^^^^^^^^^^^^^^^^^^^^^^^^^^^^^^^^^^^^^^^^^^^^^
  File "C:\Users\asd\Desktop\소공서버\venv\Lib\site-packages\django\views\decorators\csrf.py", line 65, in _view_wrapper
    return view_func(request, *args, **kwargs)
           ^^^^^^^^^^^^^^^^^^^^^^^^^^^^^^^^^^^
  File "C:\Users\asd\Desktop\소공서버\venv\Lib\site-packages\django\views\generic\base.py", line 104, in view
    return self.dispatch(request, *args, **kwargs)
           ^^^^^^^^^^^^^^^^^^^^^^^^^^^^^^^^^^^^^^^
  File "C:\Users\asd\Desktop\소공서버\venv\Lib\site-packages\rest_framework\views.py", line 515, in dispatch
    response = self.handle_exception(exc)
               ^^^^^^^^^^^^^^^^^^^^^^^^^^
  File "C:\Users\asd\Desktop\소공서버\venv\Lib\site-packages\rest_framework\views.py", line 475, in handle_exception
    self.raise_uncaught_exception(exc)
  File "C:\Users\asd\Desktop\소공서버\venv\Lib\site-packages\rest_framework\views.py", line 486, in raise_uncaught_exception
    raise exc
  File "C:\Users\asd\Desktop\소공서버\venv\Lib\site-packages\rest_framework\views.py", line 512, in dispatch
    response = handler(request, *args, **kwargs)
               ^^^^^^^^^^^^^^^^^^^^^^^^^^^^^^^^^
  File "C:\Users\asd\Desktop\CollaborationTool-back\projects\views\project_list_view.py", line 16, in get
    result = [
             ^
  File "C:\Users\asd\Desktop\소공서버\venv\Lib\site-packages\django\db\models\query.py", line 384, in __iter__
    self._fetch_all()
  File "C:\Users\asd\Desktop\소공서버\venv\Lib\site-packages\django\db\models\query.py", line 1945, in _fetch_all
    self._result_cache = list(self._iterable_class(self))
                         ^^^^^^^^^^^^^^^^^^^^^^^^^^^^^^^^
  File "C:\Users\asd\Desktop\소공서버\venv\Lib\site-packages\django\db\models\query.py", line 91, in __iter__
    results = compiler.execute_sql(
              ^^^^^^^^^^^^^^^^^^^^^
  File "C:\Users\asd\Desktop\소공서버\venv\Lib\site-packages\django\db\models\sql\compiler.py", line 1623, in execute_sql
    cursor.execute(sql, params)
  File "C:\Users\asd\Desktop\소공서버\venv\Lib\site-packages\django\db\backends\utils.py", line 122, in execute
    return super().execute(sql, params)
           ^^^^^^^^^^^^^^^^^^^^^^^^^^^^
  File "C:\Users\asd\Desktop\소공서버\venv\Lib\site-packages\django\db\backends\utils.py", line 79, in execute
    return self._execute_with_wrappers(
           ^^^^^^^^^^^^^^^^^^^^^^^^^^^^
  File "C:\Users\asd\Desktop\소공서버\venv\Lib\site-packages\django\db\backends\utils.py", line 92, in _execute_with_wrappers
    return executor(sql, params, many, context)
           ^^^^^^^^^^^^^^^^^^^^^^^^^^^^^^^^^^^^
  File "C:\Users\asd\Desktop\소공서버\venv\Lib\site-packages\django\db\backends\utils.py", line 100, in _execute
    with self.db.wrap_database_errors:
  File "C:\Users\asd\Desktop\소공서버\venv\Lib\site-packages\django\db\utils.py", line 91, in __exit__
    raise dj_exc_value.with_traceback(traceback) from exc_value
  File "C:\Users\asd\Desktop\소공서버\venv\Lib\site-packages\django\db\backends\utils.py", line 105, in _execute
    return self.cursor.execute(sql, params)
           ^^^^^^^^^^^^^^^^^^^^^^^^^^^^^^^^
  File "C:\Users\asd\Desktop\소공서버\venv\Lib\site-packages\django\db\backends\mysql\base.py", line 76, in execute
    return self.cursor.execute(query, args)
           ^^^^^^^^^^^^^^^^^^^^^^^^^^^^^^^^
  File "C:\Users\asd\Desktop\소공서버\venv\Lib\site-packages\MySQLdb\cursors.py", line 179, in execute
    res = self._query(mogrified_query)
          ^^^^^^^^^^^^^^^^^^^^^^^^^^^^
  File "C:\Users\asd\Desktop\소공서버\venv\Lib\site-packages\MySQLdb\cursors.py", line 330, in _query
    db.query(q)
  File "C:\Users\asd\Desktop\소공서버\venv\Lib\site-packages\MySQLdb\connections.py", line 280, in query
    _mysql.connection.query(self, query)
django.db.utils.OperationalError: (1054, "Unknown column 'project_members.id' in 'field list'")
2025-06-21 21:41:41,686 [WARNING] Unauthorized: /api/emailcheck/
2025-06-21 21:42:58,413 [WARNING] Unauthorized: /api/emailcheck/
2025-06-21 21:43:41,770 [WARNING] Unauthorized: /api/emailcheck/
2025-06-21 21:44:04,311 [WARNING] Unauthorized: /projects/getprojects/
2025-06-21 21:44:05,340 [WARNING] Unauthorized: /projects/getprojects/
2025-06-21 21:44:20,029 [WARNING] Unauthorized: /projects/getprojects/
2025-06-21 21:44:20,107 [WARNING] Unauthorized: /projects/getprojects/
2025-06-21 21:44:34,620 [WARNING] Unauthorized: /projects/getprojects/
2025-06-21 21:44:34,690 [WARNING] Unauthorized: /projects/getprojects/
2025-06-21 21:46:47,158 [INFO] C:\Users\asd\Desktop\CollaborationTool-back\projects\models\projectmember.py changed, reloading.
2025-06-21 21:51:41,207 [WARNING] Unauthorized: /api/emailcheck/
2025-06-21 21:52:17,341 [WARNING] Unauthorized: /api/emailcheck/
2025-06-21 21:57:53,779 [WARNING] Unauthorized: /api/emailcheck/
2025-06-21 22:04:54,997 [INFO] C:\Users\asd\Desktop\CollaborationTool-back\projects\models\projectmember.py changed, reloading.
2025-06-21 22:06:24,988 [WARNING] Unauthorized: /api/emailcheck/
2025-06-21 22:07:19,330 [WARNING] Unauthorized: /api/emailcheck/
2025-06-21 22:07:25,610 [WARNING] Unauthorized: /api/emailcheck/
2025-06-21 22:08:08,705 [WARNING] Unauthorized: /api/emailcheck/
2025-06-22 00:06:55,668 [WARNING] Not Found: /api/tasks/todo/undefined
2025-06-22 00:06:56,196 [WARNING] Not Found: /api/tasks/todo/undefined
2025-06-22 00:07:19,702 [WARNING] Not Found: /api/tasks/todo/24
2025-06-22 00:07:19,967 [WARNING] Not Found: /api/tasks/todo/23
2025-06-22 00:07:20,740 [WARNING] Not Found: /api/tasks/todo/21
2025-06-22 00:07:21,000 [WARNING] Not Found: /api/tasks/todo/20
2025-06-22 00:07:21,301 [WARNING] Not Found: /api/tasks/todo/18
2025-06-22 00:07:22,079 [WARNING] Not Found: /api/tasks/todo/17
2025-06-22 00:13:54,243 [WARNING] Unauthorized: /api/getprojects/
2025-06-22 00:13:54,248 [WARNING] Not Found: /api/tasks/todo/23
2025-06-22 00:13:54,252 [WARNING] Not Found: /api/tasks/todo/21
2025-06-22 00:13:54,256 [WARNING] Not Found: /api/tasks/todo/22
2025-06-22 00:13:54,670 [WARNING] Unauthorized: /api/getprojects/
2025-06-22 00:13:54,894 [WARNING] Unauthorized: /api/getprojects/
2025-06-22 00:13:54,898 [WARNING] Not Found: /api/tasks/todo/21
2025-06-22 00:13:55,009 [WARNING] Unauthorized: /api/getprojects/
2025-06-22 00:13:55,218 [WARNING] Unauthorized: /api/getprojects/
2025-06-22 00:13:55,221 [WARNING] Not Found: /api/tasks/todo/19
2025-06-22 00:13:59,343 [WARNING] Unauthorized: /api/getprojects/
2025-06-22 00:13:59,346 [WARNING] Not Found: /api/tasks/todo/18
2025-06-22 00:13:59,750 [WARNING] Not Found: /api/tasks/todo/19
2025-06-22 00:13:59,750 [WARNING] Unauthorized: /api/getprojects/
2025-06-22 00:14:00,110 [WARNING] Unauthorized: /api/getprojects/
2025-06-22 00:14:00,118 [WARNING] Not Found: /api/tasks/todo/20
2025-06-22 00:14:00,436 [WARNING] Unauthorized: /api/getprojects/
2025-06-22 00:14:00,443 [WARNING] Not Found: /api/tasks/todo/22
2025-06-22 00:14:01,078 [WARNING] Not Found: /api/tasks/todo/23
2025-06-22 00:14:01,079 [WARNING] Unauthorized: /api/getprojects/
2025-06-22 00:23:57,100 [INFO] C:\Users\asd\Desktop\CollaborationTool-back\SWE\settings.py changed, reloading.
2025-06-22 00:24:59,313 [WARNING] Not Found: /api/email
2025-06-22 00:25:21,380 [WARNING] Not Found: /api/email
2025-06-22 00:26:29,501 [WARNING] Not Found: /api/email
2025-06-22 00:26:41,697 [WARNING] Not Found: /api/email
2025-06-22 00:26:42,920 [WARNING] Not Found: /api/email
2025-06-22 00:30:53,924 [INFO] C:\Users\asd\Desktop\CollaborationTool-back\SWE\urls.py changed, reloading.
2025-06-22 00:32:42,496 [INFO] C:\Users\asd\Desktop\CollaborationTool-back\users\urls.py changed, reloading.
2025-06-22 00:33:10,947 [INFO] C:\Users\asd\Desktop\CollaborationTool-back\users\views\otp_view.py changed, reloading.
2025-06-22 00:33:47,777 [INFO] C:\Users\asd\Desktop\CollaborationTool-back\SWE\urls.py changed, reloading.
2025-06-22 00:42:07,556 [WARNING] Not Found: /
2025-06-22 00:42:23,183 [WARNING] Not Found: /
2025-06-22 03:25:29,531 [WARNING] Not Found: /
2025-06-22 03:30:15,338 [WARNING] Not Found: /
2025-06-22 09:52:49,472 [WARNING] Unauthorized: /api/email
2025-06-22 09:52:53,853 [WARNING] Unauthorized: /api/email
2025-06-22 09:53:03,350 [WARNING] Unauthorized: /api/email
2025-06-22 09:53:23,095 [WARNING] Unauthorized: /api/email
2025-06-22 09:54:03,925 [WARNING] Unauthorized: /api/email
2025-06-22 09:56:03,176 [WARNING] Unauthorized: /api/email
2025-06-22 09:56:51,195 [INFO] C:\Users\asd\Desktop\CollaborationTool-back\SWE\urls.py changed, reloading.
2025-06-22 10:03:31,430 [INFO] C:\Users\asd\Desktop\CollaborationTool-back\users\urls.py changed, reloading.
2025-06-22 10:03:34,755 [INFO] C:\Users\asd\Desktop\CollaborationTool-back\users\urls.py changed, reloading.
2025-06-22 10:03:46,435 [INFO] C:\Users\asd\Desktop\CollaborationTool-back\SWE\urls.py changed, reloading.
2025-06-22 10:04:29,527 [INFO] C:\Users\asd\Desktop\CollaborationTool-back\SWE\urls.py changed, reloading.
2025-06-22 10:05:03,334 [INFO] C:\Users\asd\Desktop\CollaborationTool-back\SWE\settings.py changed, reloading.
2025-06-22 10:05:30,807 [INFO] C:\Users\asd\Desktop\CollaborationTool-back\SWE\urls.py changed, reloading.
2025-06-22 10:06:13,852 [INFO] C:\Users\asd\Desktop\CollaborationTool-back\SWE\urls.py changed, reloading.
2025-06-22 10:06:24,110 [ERROR] Internal Server Error: /api/email
Traceback (most recent call last):
  File "C:\Users\asd\Desktop\소공서버\venv\Lib\site-packages\django\core\handlers\exception.py", line 55, in inner
    response = get_response(request)
               ^^^^^^^^^^^^^^^^^^^^^
  File "C:\Users\asd\Desktop\소공서버\venv\Lib\site-packages\django\utils\deprecation.py", line 122, in __call__
    response = self.process_response(request, response)
               ^^^^^^^^^^^^^^^^^^^^^^^^^^^^^^^^^^^^^^^^
  File "C:\Users\asd\Desktop\소공서버\venv\Lib\site-packages\django\middleware\common.py", line 108, in process_response
    return self.response_redirect_class(self.get_full_path_with_slash(request))
                                        ^^^^^^^^^^^^^^^^^^^^^^^^^^^^^^^^^^^^^^
  File "C:\Users\asd\Desktop\소공서버\venv\Lib\site-packages\django\middleware\common.py", line 87, in get_full_path_with_slash
    raise RuntimeError(
RuntimeError: You called this URL via POST, but the URL doesn't end in a slash and you have APPEND_SLASH set. Django can't redirect to the slash URL while maintaining POST data. Change your form to point to localhost:8000/api/email/ (note the trailing slash), or set APPEND_SLASH=False in your Django settings.
2025-06-22 10:08:55,109 [INFO] C:\Users\asd\Desktop\CollaborationTool-back\SWE\urls.py changed, reloading.
2025-06-22 10:09:13,353 [INFO] C:\Users\asd\Desktop\CollaborationTool-back\SWE\urls.py changed, reloading.
2025-06-22 10:09:19,938 [WARNING] Unauthorized: /api/email
2025-06-22 10:09:30,723 [INFO] C:\Users\asd\Desktop\CollaborationTool-back\SWE\urls.py changed, reloading.
2025-06-22 10:10:59,345 [INFO] C:\Users\asd\Desktop\CollaborationTool-back\SWE\urls.py changed, reloading.
2025-06-22 10:11:03,713 [INFO] C:\Users\asd\Desktop\CollaborationTool-back\SWE\urls.py changed, reloading.
2025-06-22 10:11:14,588 [INFO] C:\Users\asd\Desktop\CollaborationTool-back\SWE\urls.py changed, reloading.
2025-06-22 10:12:27,526 [INFO] C:\Users\asd\Desktop\CollaborationTool-back\users\views\otp_view.py changed, reloading.
2025-06-22 10:14:48,335 [ERROR] Internal Server Error: /api/email
Traceback (most recent call last):
  File "C:\Users\asd\Desktop\소공서버\venv\Lib\site-packages\django\core\handlers\exception.py", line 55, in inner
    response = get_response(request)
               ^^^^^^^^^^^^^^^^^^^^^
  File "C:\Users\asd\Desktop\소공서버\venv\Lib\site-packages\django\utils\deprecation.py", line 122, in __call__
    response = self.process_response(request, response)
               ^^^^^^^^^^^^^^^^^^^^^^^^^^^^^^^^^^^^^^^^
  File "C:\Users\asd\Desktop\소공서버\venv\Lib\site-packages\django\middleware\common.py", line 108, in process_response
    return self.response_redirect_class(self.get_full_path_with_slash(request))
                                        ^^^^^^^^^^^^^^^^^^^^^^^^^^^^^^^^^^^^^^
  File "C:\Users\asd\Desktop\소공서버\venv\Lib\site-packages\django\middleware\common.py", line 87, in get_full_path_with_slash
    raise RuntimeError(
RuntimeError: You called this URL via POST, but the URL doesn't end in a slash and you have APPEND_SLASH set. Django can't redirect to the slash URL while maintaining POST data. Change your form to point to localhost:8000/api/email/ (note the trailing slash), or set APPEND_SLASH=False in your Django settings.
2025-06-22 10:15:13,071 [WARNING] Unauthorized: /api/email/
2025-06-22 10:15:57,548 [INFO] C:\Users\asd\Desktop\CollaborationTool-back\users\views\otp_view.py changed, reloading.
2025-06-22 10:17:13,703 [ERROR] Internal Server Error: /api/email/
Traceback (most recent call last):
  File "C:\Users\asd\Desktop\소공서버\venv\Lib\site-packages\django\db\backends\utils.py", line 105, in _execute
    return self.cursor.execute(sql, params)
           ^^^^^^^^^^^^^^^^^^^^^^^^^^^^^^^^
  File "C:\Users\asd\Desktop\소공서버\venv\Lib\site-packages\django\db\backends\mysql\base.py", line 76, in execute
    return self.cursor.execute(query, args)
           ^^^^^^^^^^^^^^^^^^^^^^^^^^^^^^^^
  File "C:\Users\asd\Desktop\소공서버\venv\Lib\site-packages\MySQLdb\cursors.py", line 179, in execute
    res = self._query(mogrified_query)
          ^^^^^^^^^^^^^^^^^^^^^^^^^^^^
  File "C:\Users\asd\Desktop\소공서버\venv\Lib\site-packages\MySQLdb\cursors.py", line 330, in _query
    db.query(q)
  File "C:\Users\asd\Desktop\소공서버\venv\Lib\site-packages\MySQLdb\connections.py", line 280, in query
    _mysql.connection.query(self, query)
MySQLdb.ProgrammingError: (1146, "Table 'teamprojectdb.users_emailotp' doesn't exist")

The above exception was the direct cause of the following exception:

Traceback (most recent call last):
  File "C:\Users\asd\Desktop\소공서버\venv\Lib\site-packages\django\core\handlers\exception.py", line 55, in inner
    response = get_response(request)
               ^^^^^^^^^^^^^^^^^^^^^
  File "C:\Users\asd\Desktop\소공서버\venv\Lib\site-packages\django\core\handlers\base.py", line 197, in _get_response
    response = wrapped_callback(request, *callback_args, **callback_kwargs)
               ^^^^^^^^^^^^^^^^^^^^^^^^^^^^^^^^^^^^^^^^^^^^^^^^^^^^^^^^^^^^
  File "C:\Users\asd\Desktop\소공서버\venv\Lib\site-packages\django\views\decorators\csrf.py", line 65, in _view_wrapper
    return view_func(request, *args, **kwargs)
           ^^^^^^^^^^^^^^^^^^^^^^^^^^^^^^^^^^^
  File "C:\Users\asd\Desktop\소공서버\venv\Lib\site-packages\django\views\generic\base.py", line 104, in view
    return self.dispatch(request, *args, **kwargs)
           ^^^^^^^^^^^^^^^^^^^^^^^^^^^^^^^^^^^^^^^
  File "C:\Users\asd\Desktop\소공서버\venv\Lib\site-packages\rest_framework\views.py", line 515, in dispatch
    response = self.handle_exception(exc)
               ^^^^^^^^^^^^^^^^^^^^^^^^^^
  File "C:\Users\asd\Desktop\소공서버\venv\Lib\site-packages\rest_framework\views.py", line 475, in handle_exception
    self.raise_uncaught_exception(exc)
  File "C:\Users\asd\Desktop\소공서버\venv\Lib\site-packages\rest_framework\views.py", line 486, in raise_uncaught_exception
    raise exc
  File "C:\Users\asd\Desktop\소공서버\venv\Lib\site-packages\rest_framework\views.py", line 512, in dispatch
    response = handler(request, *args, **kwargs)
               ^^^^^^^^^^^^^^^^^^^^^^^^^^^^^^^^^
  File "C:\Users\asd\Desktop\소공서버\venv\Lib\site-packages\rest_framework\decorators.py", line 50, in handler
    return func(*args, **kwargs)
           ^^^^^^^^^^^^^^^^^^^^^
  File "C:\Users\asd\Desktop\CollaborationTool-back\users\views\otp_view.py", line 29, in send_otp
    EmailOTP.objects.update_or_create(
  File "C:\Users\asd\Desktop\소공서버\venv\Lib\site-packages\django\db\models\manager.py", line 87, in manager_method
    return getattr(self.get_queryset(), name)(*args, **kwargs)
           ^^^^^^^^^^^^^^^^^^^^^^^^^^^^^^^^^^^^^^^^^^^^^^^^^^^
  File "C:\Users\asd\Desktop\소공서버\venv\Lib\site-packages\django\db\models\query.py", line 988, in update_or_create
    obj, created = self.select_for_update().get_or_create(
                   ^^^^^^^^^^^^^^^^^^^^^^^^^^^^^^^^^^^^^^^
  File "C:\Users\asd\Desktop\소공서버\venv\Lib\site-packages\django\db\models\query.py", line 946, in get_or_create
    return self.get(**kwargs), False
           ^^^^^^^^^^^^^^^^^^
  File "C:\Users\asd\Desktop\소공서버\venv\Lib\site-packages\django\db\models\query.py", line 629, in get
    num = len(clone)
          ^^^^^^^^^^
  File "C:\Users\asd\Desktop\소공서버\venv\Lib\site-packages\django\db\models\query.py", line 366, in __len__
    self._fetch_all()
  File "C:\Users\asd\Desktop\소공서버\venv\Lib\site-packages\django\db\models\query.py", line 1945, in _fetch_all
    self._result_cache = list(self._iterable_class(self))
                         ^^^^^^^^^^^^^^^^^^^^^^^^^^^^^^^^
  File "C:\Users\asd\Desktop\소공서버\venv\Lib\site-packages\django\db\models\query.py", line 91, in __iter__
    results = compiler.execute_sql(
              ^^^^^^^^^^^^^^^^^^^^^
  File "C:\Users\asd\Desktop\소공서버\venv\Lib\site-packages\django\db\models\sql\compiler.py", line 1623, in execute_sql
    cursor.execute(sql, params)
  File "C:\Users\asd\Desktop\소공서버\venv\Lib\site-packages\django\db\backends\utils.py", line 122, in execute
    return super().execute(sql, params)
           ^^^^^^^^^^^^^^^^^^^^^^^^^^^^
  File "C:\Users\asd\Desktop\소공서버\venv\Lib\site-packages\django\db\backends\utils.py", line 79, in execute
    return self._execute_with_wrappers(
           ^^^^^^^^^^^^^^^^^^^^^^^^^^^^
  File "C:\Users\asd\Desktop\소공서버\venv\Lib\site-packages\django\db\backends\utils.py", line 92, in _execute_with_wrappers
    return executor(sql, params, many, context)
           ^^^^^^^^^^^^^^^^^^^^^^^^^^^^^^^^^^^^
  File "C:\Users\asd\Desktop\소공서버\venv\Lib\site-packages\django\db\backends\utils.py", line 100, in _execute
    with self.db.wrap_database_errors:
  File "C:\Users\asd\Desktop\소공서버\venv\Lib\site-packages\django\db\utils.py", line 91, in __exit__
    raise dj_exc_value.with_traceback(traceback) from exc_value
  File "C:\Users\asd\Desktop\소공서버\venv\Lib\site-packages\django\db\backends\utils.py", line 105, in _execute
    return self.cursor.execute(sql, params)
           ^^^^^^^^^^^^^^^^^^^^^^^^^^^^^^^^
  File "C:\Users\asd\Desktop\소공서버\venv\Lib\site-packages\django\db\backends\mysql\base.py", line 76, in execute
    return self.cursor.execute(query, args)
           ^^^^^^^^^^^^^^^^^^^^^^^^^^^^^^^^
  File "C:\Users\asd\Desktop\소공서버\venv\Lib\site-packages\MySQLdb\cursors.py", line 179, in execute
    res = self._query(mogrified_query)
          ^^^^^^^^^^^^^^^^^^^^^^^^^^^^
  File "C:\Users\asd\Desktop\소공서버\venv\Lib\site-packages\MySQLdb\cursors.py", line 330, in _query
    db.query(q)
  File "C:\Users\asd\Desktop\소공서버\venv\Lib\site-packages\MySQLdb\connections.py", line 280, in query
    _mysql.connection.query(self, query)
django.db.utils.ProgrammingError: (1146, "Table 'teamprojectdb.users_emailotp' doesn't exist")
2025-06-22 10:18:53,302 [ERROR] Internal Server Error: /api/email/
Traceback (most recent call last):
  File "C:\Users\asd\Desktop\소공서버\venv\Lib\site-packages\django\db\backends\utils.py", line 105, in _execute
    return self.cursor.execute(sql, params)
           ^^^^^^^^^^^^^^^^^^^^^^^^^^^^^^^^
  File "C:\Users\asd\Desktop\소공서버\venv\Lib\site-packages\django\db\backends\mysql\base.py", line 76, in execute
    return self.cursor.execute(query, args)
           ^^^^^^^^^^^^^^^^^^^^^^^^^^^^^^^^
  File "C:\Users\asd\Desktop\소공서버\venv\Lib\site-packages\MySQLdb\cursors.py", line 179, in execute
    res = self._query(mogrified_query)
          ^^^^^^^^^^^^^^^^^^^^^^^^^^^^
  File "C:\Users\asd\Desktop\소공서버\venv\Lib\site-packages\MySQLdb\cursors.py", line 330, in _query
    db.query(q)
  File "C:\Users\asd\Desktop\소공서버\venv\Lib\site-packages\MySQLdb\connections.py", line 280, in query
    _mysql.connection.query(self, query)
MySQLdb.ProgrammingError: (1146, "Table 'teamprojectdb.users_emailotp' doesn't exist")

The above exception was the direct cause of the following exception:

Traceback (most recent call last):
  File "C:\Users\asd\Desktop\소공서버\venv\Lib\site-packages\django\core\handlers\exception.py", line 55, in inner
    response = get_response(request)
               ^^^^^^^^^^^^^^^^^^^^^
  File "C:\Users\asd\Desktop\소공서버\venv\Lib\site-packages\django\core\handlers\base.py", line 197, in _get_response
    response = wrapped_callback(request, *callback_args, **callback_kwargs)
               ^^^^^^^^^^^^^^^^^^^^^^^^^^^^^^^^^^^^^^^^^^^^^^^^^^^^^^^^^^^^
  File "C:\Users\asd\Desktop\소공서버\venv\Lib\site-packages\django\views\decorators\csrf.py", line 65, in _view_wrapper
    return view_func(request, *args, **kwargs)
           ^^^^^^^^^^^^^^^^^^^^^^^^^^^^^^^^^^^
  File "C:\Users\asd\Desktop\소공서버\venv\Lib\site-packages\django\views\generic\base.py", line 104, in view
    return self.dispatch(request, *args, **kwargs)
           ^^^^^^^^^^^^^^^^^^^^^^^^^^^^^^^^^^^^^^^
  File "C:\Users\asd\Desktop\소공서버\venv\Lib\site-packages\rest_framework\views.py", line 515, in dispatch
    response = self.handle_exception(exc)
               ^^^^^^^^^^^^^^^^^^^^^^^^^^
  File "C:\Users\asd\Desktop\소공서버\venv\Lib\site-packages\rest_framework\views.py", line 475, in handle_exception
    self.raise_uncaught_exception(exc)
  File "C:\Users\asd\Desktop\소공서버\venv\Lib\site-packages\rest_framework\views.py", line 486, in raise_uncaught_exception
    raise exc
  File "C:\Users\asd\Desktop\소공서버\venv\Lib\site-packages\rest_framework\views.py", line 512, in dispatch
    response = handler(request, *args, **kwargs)
               ^^^^^^^^^^^^^^^^^^^^^^^^^^^^^^^^^
  File "C:\Users\asd\Desktop\소공서버\venv\Lib\site-packages\rest_framework\decorators.py", line 50, in handler
    return func(*args, **kwargs)
           ^^^^^^^^^^^^^^^^^^^^^
  File "C:\Users\asd\Desktop\CollaborationTool-back\users\views\otp_view.py", line 29, in send_otp
    EmailOTP.objects.update_or_create(
  File "C:\Users\asd\Desktop\소공서버\venv\Lib\site-packages\django\db\models\manager.py", line 87, in manager_method
    return getattr(self.get_queryset(), name)(*args, **kwargs)
           ^^^^^^^^^^^^^^^^^^^^^^^^^^^^^^^^^^^^^^^^^^^^^^^^^^^
  File "C:\Users\asd\Desktop\소공서버\venv\Lib\site-packages\django\db\models\query.py", line 988, in update_or_create
    obj, created = self.select_for_update().get_or_create(
                   ^^^^^^^^^^^^^^^^^^^^^^^^^^^^^^^^^^^^^^^
  File "C:\Users\asd\Desktop\소공서버\venv\Lib\site-packages\django\db\models\query.py", line 946, in get_or_create
    return self.get(**kwargs), False
           ^^^^^^^^^^^^^^^^^^
  File "C:\Users\asd\Desktop\소공서버\venv\Lib\site-packages\django\db\models\query.py", line 629, in get
    num = len(clone)
          ^^^^^^^^^^
  File "C:\Users\asd\Desktop\소공서버\venv\Lib\site-packages\django\db\models\query.py", line 366, in __len__
    self._fetch_all()
  File "C:\Users\asd\Desktop\소공서버\venv\Lib\site-packages\django\db\models\query.py", line 1945, in _fetch_all
    self._result_cache = list(self._iterable_class(self))
                         ^^^^^^^^^^^^^^^^^^^^^^^^^^^^^^^^
  File "C:\Users\asd\Desktop\소공서버\venv\Lib\site-packages\django\db\models\query.py", line 91, in __iter__
    results = compiler.execute_sql(
              ^^^^^^^^^^^^^^^^^^^^^
  File "C:\Users\asd\Desktop\소공서버\venv\Lib\site-packages\django\db\models\sql\compiler.py", line 1623, in execute_sql
    cursor.execute(sql, params)
  File "C:\Users\asd\Desktop\소공서버\venv\Lib\site-packages\django\db\backends\utils.py", line 122, in execute
    return super().execute(sql, params)
           ^^^^^^^^^^^^^^^^^^^^^^^^^^^^
  File "C:\Users\asd\Desktop\소공서버\venv\Lib\site-packages\django\db\backends\utils.py", line 79, in execute
    return self._execute_with_wrappers(
           ^^^^^^^^^^^^^^^^^^^^^^^^^^^^
  File "C:\Users\asd\Desktop\소공서버\venv\Lib\site-packages\django\db\backends\utils.py", line 92, in _execute_with_wrappers
    return executor(sql, params, many, context)
           ^^^^^^^^^^^^^^^^^^^^^^^^^^^^^^^^^^^^
  File "C:\Users\asd\Desktop\소공서버\venv\Lib\site-packages\django\db\backends\utils.py", line 100, in _execute
    with self.db.wrap_database_errors:
  File "C:\Users\asd\Desktop\소공서버\venv\Lib\site-packages\django\db\utils.py", line 91, in __exit__
    raise dj_exc_value.with_traceback(traceback) from exc_value
  File "C:\Users\asd\Desktop\소공서버\venv\Lib\site-packages\django\db\backends\utils.py", line 105, in _execute
    return self.cursor.execute(sql, params)
           ^^^^^^^^^^^^^^^^^^^^^^^^^^^^^^^^
  File "C:\Users\asd\Desktop\소공서버\venv\Lib\site-packages\django\db\backends\mysql\base.py", line 76, in execute
    return self.cursor.execute(query, args)
           ^^^^^^^^^^^^^^^^^^^^^^^^^^^^^^^^
  File "C:\Users\asd\Desktop\소공서버\venv\Lib\site-packages\MySQLdb\cursors.py", line 179, in execute
    res = self._query(mogrified_query)
          ^^^^^^^^^^^^^^^^^^^^^^^^^^^^
  File "C:\Users\asd\Desktop\소공서버\venv\Lib\site-packages\MySQLdb\cursors.py", line 330, in _query
    db.query(q)
  File "C:\Users\asd\Desktop\소공서버\venv\Lib\site-packages\MySQLdb\connections.py", line 280, in query
    _mysql.connection.query(self, query)
django.db.utils.ProgrammingError: (1146, "Table 'teamprojectdb.users_emailotp' doesn't exist")
